Workbook

Sheet 総括PL_実績(MA前合算)
B2: グループ簡易合算 | F2: 46113 | G2: 46143 | H2: 46174 | I2: 46204 | J2: 46235 | K2: 46266 | L2: 46296 | M2: 46327 | N2: 46357 | O2: 46388 | P2: 46419 | Q2: 46447
B3: 売上高 | D3: Revenue | F3: =F80 -> 1934128209
B4: 商品売上原価 | D4: COGS | F4: =F81
B5: 売上総利益 | D5: Gross Profit | F5: =F3-F4
B6: SGA | D6: SGA | F6: =F83
B7: 営業損益 | D7: Operating Profit | F7: =F5-F6
B8: 営業外損益 | D8: Non-Operating Profit | F8: =F85-F86+F73
B9: 経常損益 | D9: Ordinary Profit | F9: =F7+F8
B12: 代々木アニメーショングループ | D12: UTAITE | F12: 46113
B13: 売上高 | D13: Revenue | F13: =F99 -> 43119318
B14: 商品売上原価 | D14: COGS | F14: =F100 -> 6959949
B15: 売上総利益 | D15: Gross Profit | F15: =F13-F14 -> 36159369
B16: SGA | D16: SGA | F16: =F102 -> 34449924
B17: 営業損益 | D17: Operating Profit | F17: =F15-F16 -> 1709445
B18: 営業外損益 | D18: Non-Operating Profit | F18: =F104-F105 -> -42191841
B19: 経常損益 | D19: Ordinary Profit | F19: =F17+F18 -> -40482396
B22: Cynra | D22: Cynra | F22: 46113
B23: 売上高 | D23: Revenue | F23: =F117 -> 21265200
B24: 商品売上原価 | D24: COGS | F24: =F118 -> 13187465
B25: 売上総利益 | D25: Gross Profit | F25: =F119 -> 8077735
B26: SGA | D26: SGA | F26: =F120 -> 2532557
B27: 営業損益 | D27: Operating Profit | F27: =F121 -> 5545178
B28: 営業外損益 | D28: Non-Operating Profit | F28: =F122-F123 -> -7238
B29: 経常損益 | D29: Ordinary Profit | F29: =F124 -> 5537940
B32: V社G | D32: VOISING | F32: 46113
B33: 売上高 | D33: Revenue | F33: =F135 -> 136063159
B34: 商品売上原価 | D34: COGS | F34: =F136 -> 157236848
B35: 売上総利益 | D35: Gross Profit | F35: =F137 -> -21173689
B36: SGA | D36: SGA | F36: =F138
B37: 営業損益 | D37: Operating Profit | F37: =F139
B38: 営業外損益 | D38: Non-Operating Profit | F38: =F140-F141
B39: 経常損益 | D39: Ordinary Profit | F39: =F142
B42: 英字)UTAITE | F42: 46113
B43: 売上高 | D43: Revenue | F43: =F160 -> 0
B44: 商品売上原価 | D44: COGS | F44: =F161
B45: 売上総利益 | D45: Gross Profit | F45: =F162
B46: SGA | D46: SGA | F46: =F163
B47: 営業損益 | D47: Operating Profit | F47: =F164
B48: 営業外損益 | D48: Non-Operating Profit | F48: =F165-F166
B49: 経常損益 | D49: Ordinary Profit | F49: =F167
...

Sheet YGR_PL
B1: ②マスタ結びつけ | C1: ① | D1: 月次推移：損益計算書_株式会社代々木アニメーショングループ（期間：2026年04月〜2027年03月、表示単位：円）
J2: 46113 | K2: 46143 | L2: 46174 | M2: 46204 | N2: 46235 | O2: 46266 | P2: 46296 | Q2: 46327 | R2: 46357 | S2: 46388 | T2: 46419 | U2: 46447 | V2: 期間累計
D3: 売上高
A4: {=XLOOKUP(C4, 'マスタ'!$C$2:$C$312, 'マスタ'!$D$2:$D$312, "マスタ未登録")} -> 売上高 | B4: =IF(AND(C4<>"", COUNTIF('マスタ'!$C:$C, C4)=0), "マスタ未登録", "") | C4: =D4&D109&E4&F4&G4&H4 -> 売上高 | E4: 売上高 | J4: 43119318 | K4: 53884627 | L4: 43374767 | M4: 43380000 | N4: 43380000 | O4: 43380000 | P4: 0 | Q4: 0 | R4: 0 | S4: 0 | T4: 0 | U4: 0 | V4: 270518712
A5: {=XLOOKUP(C5, 'マスタ'!$C$2:$C$312, 'マスタ'!$D$2:$D$312, "マスタ未登録")} -> マスタ未登録 | B5: =IF(AND(C5<>"", COUNTIF('マスタ'!$C:$C, C5)=0), "マスタ未登録", "") -> マスタ未登録 | C5: =D5&D110&E5&F5&G5&H5 -> 売上高 計 | D5: 売上高 計 | J5: 43119318 | K5: 53884627 | L5: 43374767 | M5: 43380000 | N5: 43380000 | O5: 43380000 | P5: 0 | Q5: 0 | R5: 0 | S5: 0 | T5: 0 | U5: 0 | V5: 270518712
A6: {=XLOOKUP(C6, 'マスタ'!$C$2:$C$312, 'マスタ'!$D$2:$D$312, "マスタ未登録")} -> マスタ未登録 | B6: =IF(AND(C6<>"", COUNTIF('マスタ'!$C:$C, C6)=0), "マスタ未登録", "") -> マスタ未登録 | C6: =D6&D111&E6&F6&G6&H6 -> 売上原価 | E6: 売上原価
A7: {=XLOOKUP(C7, 'マスタ'!$C$2:$C$312, 'マスタ'!$D$2:$D$312, "マスタ未登録")} -> マスタ未登録 | B7: =IF(AND(C7<>"", COUNTIF('マスタ'!$C:$C, C7)=0), "マスタ未登録", "") -> マスタ未登録 | C7: =D7&D112&E7&F7&G7&H7 -> 売上原価 | E7: 売上原価 | J7: 6959949 | K7: 2620001 | L7: 0 | M7: 0 | N7: 0 | O7: 0 | P7: 0 | Q7: 0 | R7: 0 | S7: 0 | T7: 0 | U7: 0 | V7: 9579950
A8: {=XLOOKUP(C8, 'マスタ'!$C$2:$C$312, 'マスタ'!$D$2:$D$312, "マスタ未登録")} -> 期首商品棚卸高 | B8: =IF(AND(C8<>"", COUNTIF('マスタ'!$C:$C, C8)=0), "マスタ未登録", "") | C8: =D8&D113&E8&F8&G8&H8 -> 期首商品棚卸 | G8: 期首商品棚卸 | J8: 1886546 | K8: 0 | L8: 0 | M8: 0 | N8: 0 | O8: 0 | P8: 0 | Q8: 0 | R8: 0 | S8: 0 | T8: 0 | U8: 0 | V8: 1886546
A9: {=XLOOKUP(C9, 'マスタ'!$C$2:$C$312, 'マスタ'!$D$2:$D$312, "マスタ未登録")} -> 期首商品棚卸高 | B9: =IF(AND(C9<>"", COUNTIF('マスタ'!$C:$C, C9)=0), "マスタ未登録", "") | C9: =D9&D114&E9&F9&G9&H9 -> 期首商品棚卸高 | H9: 期首商品棚卸高 | J9: 1886546 | K9: 0 | L9: 0 | M9: 0 | N9: 0 | O9: 0 | P9: 0 | Q9: 0 | R9: 0 | S9: 0 | T9: 0 | U9: 0 | V9: 1886546
A10: {=XLOOKUP(C10, 'マスタ'!$C$2:$C$312, 'マスタ'!$D$2:$D$312, "マスタ未登録")} -> 当期商品仕入高 | B10: =IF(AND(C10<>"", COUNTIF('マスタ'!$C:$C, C10)=0), "マスタ未登録", "") | C10: =D10&D115&E10&F10&G10&H10 -> 当期商品仕入 | G10: 当期商品仕入 | J10: 5788844 | K10: 2620001 | L10: 0 | M10: 0 | N10: 0 | O10: 0 | P10: 0 | Q10: 0 | R10: 0 | S10: 0 | T10: 0 | U10: 0 | V10: 8408845
A11: {=XLOOKUP(C11, 'マスタ'!$C$2:$C$312, 'マスタ'!$D$2:$D$312, "マスタ未登録")} -> 当期商品仕入高 | B11: =IF(AND(C11<>"", COUNTIF('マスタ'!$C:$C, C11)=0), "マスタ未登録", "") | C11: =D11&D116&E11&F11&G11&H11 -> 給料手当(原) | H11: 給料手当(原) | J11: 3666203 | K11: 1915784 | L11: 0 | M11: 0 | N11: 0 | O11: 0 | P11: 0 | Q11: 0 | R11: 0 | S11: 0 | T11: 0 | U11: 0 | V11: 5581987
A12: {=XLOOKUP(C12, 'マスタ'!$C$2:$C$312, 'マスタ'!$D$2:$D$312, "マスタ未登録")} -> 当期商品仕入高 | B12: =IF(AND(C12<>"", COUNTIF('マスタ'!$C:$C, C12)=0), "マスタ未登録", "") | C12: =D12&D117&E12&F12&G12&H12 -> 法定福利費(原) | H12: 法定福利費(原) | J12: 574947 | K12: 274625 | L12: 0 | M12: 0 | N12: 0 | O12: 0 | P12: 0 | Q12: 0 | R12: 0 | S12: 0 | T12: 0 | U12: 0 | V12: 849572
A13: {=XLOOKUP(C13, 'マスタ'!$C$2:$C$312, 'マスタ'!$D$2:$D$312, "マスタ未登録")} -> 当期商品仕入高 | B13: =IF(AND(C13<>"", COUNTIF('マスタ'!$C:$C, C13)=0), "マスタ未登録", "") | C13: =D13&D118&E13&F13&G13&H13 -> 外注費(原) | H13: 外注費(原) | J13: 1173000 | K13: 380000 | L13: 0 | M13: 0 | N13: 0 | O13: 0 | P13: 0 | Q13: 0 | R13: 0 | S13: 0 | T13: 0 | U13: 0 | V13: 1553000
A14: {=XLOOKUP(C14, 'マスタ'!$C$2:$C$312, 'マスタ'!$D$2:$D$312, "マスタ未登録")} -> 当期商品仕入高 | B14: =IF(AND(C14<>"", COUNTIF('マスタ'!$C:$C, C14)=0), "マスタ未登録", "") | C14: =D14&D119&E14&F14&G14&H14 -> 業務委託費(原) | H14: 業務委託費(原) | J14: 269139 | K14: 1 | L14: 0 | M14: 0 | N14: 0 | O14: 0 | P14: 0 | Q14: 0 | R14: 0 | S14: 0 | T14: 0 | U14: 0 | V14: 269140
A15: {=XLOOKUP(C15, 'マスタ'!$C$2:$C$312, 'マスタ'!$D$2:$D$312, "マスタ未登録")} -> 当期商品仕入高 | B15: =IF(AND(C15<>"", COUNTIF('マスタ'!$C:$C, C15)=0), "マスタ未登録", "") | C15: =D15&D120&E15&F15&G15&H15 -> 旅費交通費(原) | H15: 旅費交通費(原) | J15: 105355 | K15: 49591 | L15: 0 | M15: 0 | N15: 0 | O15: 0 | P15: 0 | Q15: 0 | R15: 0 | S15: 0 | T15: 0 | U15: 0 | V15: 154946
A16: {=XLOOKUP(C16, 'マスタ'!$C$2:$C$312, 'マスタ'!$D$2:$D$312, "マスタ未登録")} -> 当期商品仕入高 | B16: =IF(AND(C16<>"", COUNTIF('マスタ'!$C:$C, C16)=0), "マスタ未登録", "") | C16: =D16&D121&E16&F16&G16&H16 -> 消耗品費(原) | H16: 消耗品費(原) | J16: 200 | K16: 0 | L16: 0 | M16: 0 | N16: 0 | O16: 0 | P16: 0 | Q16: 0 | R16: 0 | S16: 0 | T16: 0 | U16: 0 | V16: 200
A17: {=XLOOKUP(C17, 'マスタ'!$C$2:$C$312, 'マスタ'!$D$2:$D$312, "マスタ未登録")} -> 他勘定振替高 | B17: =IF(AND(C17<>"", COUNTIF('マスタ'!$C:$C, C17)=0), "マスタ未登録", "") | C17: =D17&D122&E17&F17&G17&H17 -> 他勘定振替高(商) | G17: 他勘定振替高(商) | J17: 0 | K17: 0 | L17: 0 | M17: 0 | N17: 0 | O17: 0 | P17: 0 | Q17: 0 | R17: 0 | S17: 0 | T17: 0 | U17: 0 | V17: 0
A18: {=XLOOKUP(C18, 'マスタ'!$C$2:$C$312, 'マスタ'!$D$2:$D$312, "マスタ未登録")} -> 期末商品棚卸高 | B18: =IF(AND(C18<>"", COUNTIF('マスタ'!$C:$C, C18)=0), "マスタ未登録", "") | C18: =D18&D123&E18&F18&G18&H18 -> 期末商品棚卸 | G18: 期末商品棚卸 | J18: 715441 | K18: 0 | L18: 0 | M18: 0 | N18: 0 | O18: 0 | P18: 0 | Q18: 0 | R18: 0 | S18: 0 | T18: 0 | U18: 0 | V18: 715441
A19: {=XLOOKUP(C19, 'マスタ'!$C$2:$C$312, 'マスタ'!$D$2:$D$312, "マスタ未登録")} -> 期末商品棚卸高 | B19: =IF(AND(C19<>"", COUNTIF('マスタ'!$C:$C, C19)=0), "マスタ未登録", "") | C19: =D19&D124&E19&F19&G19&H19 -> 期末商品棚卸高 | H19: 期末商品棚卸高 | J19: 715441 | K19: 0 | L19: 0 | M19: 0 | N19: 0 | O19: 0 | P19: 0 | Q19: 0 | R19: 0 | S19: 0 | T19: 0 | U19: 0 | V19: 715441
A20: {=XLOOKUP(C20, 'マスタ'!$C$2:$C$312, 'マスタ'!$D$2:$D$312, "マスタ未登録")} -> マスタ未登録 | B20: =IF(AND(C20<>"", COUNTIF('マスタ'!$C:$C, C20)=0), "マスタ未登録", "") -> マスタ未登録 | C20: =D20&D125&E20&F20&G20&H20 -> 商品売上原価 | F20: 商品売上原価 | J20: 6959949 | K20: 2620001 | L20: 0 | M20: 0 | N20: 0 | O20: 0 | P20: 0 | Q20: 0 | R20: 0 | S20: 0 | T20: 0 | U20: 0 | V20: 9579950
A21: {=XLOOKUP(C21, 'マスタ'!$C$2:$C$312, 'マスタ'!$D$2:$D$312, "マスタ未登録")} -> マスタ未登録 | B21: =IF(AND(C21<>"", COUNTIF('マスタ'!$C:$C, C21)=0), "マスタ未登録", "") -> マスタ未登録 | C21: =D21&D126&E21&F21&G21&H21 -> 売上総損益金額 | D21: 売上総損益金額 | J21: 36159369 | K21: 51264626 | L21: 43374767 | M21: 43380000 | N21: 43380000 | O21: 43380000 | P21: 0 | Q21: 0 | R21: 0 | S21: 0 | T21: 0 | U21: 0 | V21: 260938762
A22: {=XLOOKUP(C22, 'マスタ'!$C$2:$C$312, 'マスタ'!$D$2:$D$312, "マスタ未登録")} -> マスタ未登録 | B22: =IF(AND(C22<>"", COUNTIF('マスタ'!$C:$C, C22)=0), "マスタ未登録", "") -> マスタ未登録 | C22: =D22&D127&E22&F22&G22&H22 -> 販売管理費 | E22: 販売管理費
A23: {=XLOOKUP(C23, 'マスタ'!$C$2:$C$312, 'マスタ'!$D$2:$D$312, "マスタ未登録")} -> 役員報酬 | B23: =IF(AND(C23<>"", COUNTIF('マスタ'!$C:$C, C23)=0), "マスタ未登録", "") | C23: =D23&D128&E23&F23&G23&H23 -> 役員報酬 | F23: 役員報酬 | J23: 3650000 | K23: 3650000 | L23: 3650000 | M23: 0 | N23: 0 | O23: 0 | P23: 0 | Q23: 0 | R23: 0 | S23: 0 | T23: 0 | U23: 0 | V23: 10950000
A24: {=XLOOKUP(C24, 'マスタ'!$C$2:$C$312, 'マスタ'!$D$2:$D$312, "マスタ未登録")} -> 給料手当 | B24: =IF(AND(C24<>"", COUNTIF('マスタ'!$C:$C, C24)=0), "マスタ未登録", "") | C24: =D24&D129&E24&F24&G24&H24 -> 給料手当 | F24: 給料手当 | J24: 1906725 | K24: 1073609 | L24: 0 | M24: 0 | N24: 0 | O24: 0 | P24: 0 | Q24: 0 | R24: 0 | S24: 0 | T24: 0 | U24: 0 | V24: 2980334
A25: {=XLOOKUP(C25, 'マスタ'!$C$2:$C$312, 'マスタ'!$D$2:$D$312, "マスタ未登録")} -> 法定福利費 | B25: =IF(AND(C25<>"", COUNTIF('マスタ'!$C:$C, C25)=0), "マスタ未登録", "") | C25: =D25&D130&E25&F25&G25&H25 -> 法定福利費 | F25: 法定福利費 | J25: 688384 | K25: 378471 | L25: 409505 | M25: 0 | N25: 0 | O25: 0 | P25: 0 | Q25: 0 | R25: 0 | S25: 0 | T25: 0 | U25: 0 | V25: 1476360
A26: {=XLOOKUP(C26, 'マスタ'!$C$2:$C$312, 'マスタ'!$D$2:$D$312, "マスタ未登録")} -> 株式報酬費用 | B26: =IF(AND(C26<>"", COUNTIF('マスタ'!$C:$C, C26)=0), "マスタ未登録", "") | C26: =D26&D131&E26&F26&G26&H26 -> 株式報酬費用 | F26: 株式報酬費用 | J26: 17395635 | K26: 17395635 | L26: 17395635 | M26: 16543881 | N26: 16543881 | O26: 16543881 | P26: 16543881 | Q26: 16543881 | R26: 16543881 | S26: 16543881 | T26: 16543881 | U26: 16543874 | V26: 201081827
A27: {=XLOOKUP(C27, 'マスタ'!$C$2:$C$312, 'マスタ'!$D$2:$D$312, "マスタ未登録")} -> 旅費交通費 | B27: =IF(AND(C27<>"", COUNTIF('マスタ'!$C:$C, C27)=0), "マスタ未登録", "") | C27: =D27&D132&E27&F27&G27&H27 -> 旅費交通費 | F27: 旅費交通費 | J27: 1009055 | K27: 302890 | L27: 17846 | M27: 0 | N27: 0 | O27: 0 | P27: 0 | Q27: 0 | R27: 0 | S27: 0 | T27: 0 | U27: 0 | V27: 1329791
A28: {=XLOOKUP(C28, 'マスタ'!$C$2:$C$312, 'マスタ'!$D$2:$D$312, "マスタ未登録")} -> 通信費 | B28: =IF(AND(C28<>"", COUNTIF('マスタ'!$C:$C, C28)=0), "マスタ未登録", "") | C28: =D28&D133&E28&F28&G28&H28 -> 通信費 | F28: 通信費 | J28: 394197 | K28: 1521086 | L28: 43630 | M28: 0 | N28: 0 | O28: 0 | P28: 0 | Q28: 0 | R28: 0 | S28: 0 | T28: 0 | U28: 0 | V28: 1958913
A29: {=XLOOKUP(C29, 'マスタ'!$C$2:$C$312, 'マスタ'!$D$2:$D$312, "マスタ未登録")} -> 採用教育費 | B29: =IF(AND(C29<>"", COUNTIF('マスタ'!$C:$C, C29)=0), "マスタ未登録", "") | C29: =D29&D134&E29&F29&G29&H29 -> 採用教育費 | F29: 採用教育費 | J29: 1155634 | K29: 755634 | L29: 700634 | M29: 700634 | N29: 590634 | O29: 590634 | P29: 423967 | Q29: 423967 | R29: 296467 | S29: 296467 | T29: 296470 | U29: 61169 | V29: 6292311
A30: {=XLOOKUP(C30, 'マスタ'!$C$2:$C$312, 'マスタ'!$D$2:$D$312, "マスタ未登録")} -> 業務委託費 | B30: =IF(AND(C30<>"", COUNTIF('マスタ'!$C:$C, C30)=0), "マスタ未登録", "") | C30: =D30&D135&E30&F30&G30&H30 -> 業務委託費 | F30: 業務委託費 | J30: 2015176 | K30: 1218548 | L30: 0 | M30: 0 | N30: 0 | O30: 0 | P30: 0 | Q30: 0 | R30: 0 | S30: 0 | T30: 0 | U30: 0 | V30: 3233724
A31: {=XLOOKUP(C31, 'マスタ'!$C$2:$C$312, 'マスタ'!$D$2:$D$312, "マスタ未登録")} -> 支払報酬 | B31: =IF(AND(C31<>"", COUNTIF('マスタ'!$C:$C, C31)=0), "マスタ未登録", "") | C31: =D31&D136&E31&F31&G31&H31 -> 支払報酬料 | F31: 支払報酬料 | J31: 2275000 | K31: 2585000 | L31: 250000 | M31: 0 | N31: 0 | O31: 0 | P31: 0 | Q31: 0 | R31: 0 | S31: 0 | T31: 0 | U31: 0 | V31: 5110000
A32: {=XLOOKUP(C32, 'マスタ'!$C$2:$C$312, 'マスタ'!$D$2:$D$312, "マスタ未登録")} -> 荷造運賃 | B32: =IF(AND(C32<>"", COUNTIF('マスタ'!$C:$C, C32)=0), "マスタ未登録", "") | C32: =D32&D137&E32&F32&G32&H32 -> 荷造運賃 | F32: 荷造運賃 | J32: 20359 | K32: 33608 | L32: 0 | M32: 0 | N32: 0 | O32: 0 | P32: 0 | Q32: 0 | R32: 0 | S32: 0 | T32: 0 | U32: 0 | V32: 53967
A33: {=XLOOKUP(C33, 'マスタ'!$C$2:$C$312, 'マスタ'!$D$2:$D$312, "マスタ未登録")} -> 支払手数料 | B33: =IF(AND(C33<>"", COUNTIF('マスタ'!$C:$C, C33)=0), "マスタ未登録", "") | C33: =D33&D138&E33&F33&G33&H33 -> 支払手数料 | F33: 支払手数料 | J33: 28224 | K33: 251913 | L33: 4000 | M33: 0 | N33: 0 | O33: 0 | P33: 0 | Q33: 0 | R33: 0 | S33: 0 | T33: 0 | U33: 0 | V33: 284137
A34: {=XLOOKUP(C34, 'マスタ'!$C$2:$C$312, 'マスタ'!$D$2:$D$312, "マスタ未登録")} -> 地代家賃 | B34: =IF(AND(C34<>"", COUNTIF('マスタ'!$C:$C, C34)=0), "マスタ未登録", "") | C34: =D34&D139&E34&F34&G34&H34 -> 地代家賃 | F34: 地代家賃 | J34: 625659 | K34: 0 | L34: 0 | M34: 0 | N34: 0 | O34: 0 | P34: 0 | Q34: 0 | R34: 0 | S34: 0 | T34: 0 | U34: 0 | V34: 625659
... A41: {=XLOOKUP(C41, 'マスタ'!$C$2:$C$312, 'マスタ'!$D$2:$D$312, "マスタ未登録")} -> 減価償却費 | B41: =IF(AND(C41<>"", COUNTIF('マスタ'!$C:$C, C41)=0), "マスタ未登録", "") | C41: =D41&D146&E41&F41&G41&H41 -> 減価償却費 | F41: 減価償却費 | J41: 254649 | K41: 246513 | L41: 250174 | M41: 250174 | N41: 250174 | O41: 250174 | P41: 250174 | Q41: 250174 | R41: 250174 | S41: 250174 | T41: 250174 | U41: 250499 | V41: 3003227
A42: {=XLOOKUP(C42, 'マスタ'!$C$2:$C$312, 'マスタ'!$D$2:$D$312, "マスタ未登録")} -> マスタ未登録 | B42: =IF(AND(C42<>"", COUNTIF('マスタ'!$C:$C, C42)=0), "マスタ未登録", "") -> マスタ未登録 | C42: =D42&D147&E42&F42&G42&H42 -> 販売管理費 計 | E42: 販売管理費 計 | J42: 34449924 | K42: 29900156 | L42: 22779878 | M42: 17494689 | N42: 17384689 | O42: 17384689 | P42: 17218022 | Q42: 17218022 | R42: 17090522 | S42: 17090522 | T42: 17090525 | U42: 16855542 | V42: 241957180
A43: {=XLOOKUP(C43, 'マスタ'!$C$2:$C$312, 'マスタ'!$D$2:$D$312, "マスタ未登録")} -> マスタ未登録 | B43: =IF(AND(C43<>"", COUNTIF('マスタ'!$C:$C, C43)=0), "マスタ未登録", "") -> マスタ未登録 | C43: =D43&D148&E43&F43&G43&H43 -> 営業損益金額 | D43: 営業損益金額 | J43: 1709445 | K43: 21364470 | L43: 20594889 | M43: 25885311 | N43: 25995311 | O43: 25995311 | P43: -17218022 | Q43: -17218022 | R43: -17090522 | S43: -17090522 | T43: -17090525 | U43: -16855542 | V43: 18981582
A44: {=XLOOKUP(C44, 'マスタ'!$C$2:$C$312, 'マスタ'!$D$2:$D$312, "マスタ未登録")} -> マスタ未登録 | B44: =IF(AND(C44<>"", COUNTIF('マスタ'!$C:$C, C44)=0), "マスタ未登録", "") -> マスタ未登録 | C44: =D44&D149&E44&F44&G44&H44 -> 営業外収益 | E44: 営業外収益 | J44: 1392416 | K44: 23741 | L44: 11342 | M44: 0 | N44: 0 | O44: 0 | P44: 0 | Q44: 0 | R44: 0 | S44: 0 | T44: 0 | U44: 0 | V44: 1427499
A45: {=XLOOKUP(C45, 'マスタ'!$C$2:$C$312, 'マスタ'!$D$2:$D$312, "マスタ未登録")} -> 受取利息 | B45: =IF(AND(C45<>"", COUNTIF('マスタ'!$C:$C, C45)=0), "マスタ未登録", "") | C45: =D45&D150&E45&F45&G45&H45 -> 受取利息 | F45: 受取利息 | J45: 12583 | K45: 11063 | L45: 11342 | M45: 0 | N45: 0 | O45: 0 | P45: 0 | Q45: 0 | R45: 0 | S45: 0 | T45: 0 | U45: 0 | V45: 34988
A46: {=XLOOKUP(C46, 'マスタ'!$C$2:$C$312, 'マスタ'!$D$2:$D$312, "マスタ未登録")} -> 雑収入 | B46: =IF(AND(C46<>"", COUNTIF('マスタ'!$C:$C, C46)=0), "マスタ未登録", "") | C46: =D46&D151&E46&F46&G46&H46 -> 雑収入 | F46: 雑収入 | J46: 1379833 | K46: 12678 | L46: 0 | M46: 0 | N46: 0 | O46: 0 | P46: 0 | Q46: 0 | R46: 0 | S46: 0 | T46: 0 | U46: 0 | V46: 1392511
...

Sheet YG_PL(M)
A1: PL(M) のコピー | AP1: 28444299
E2: 留意事項 | AP2: -36774467
E3: ・下記FMTでウタイテ連結の事業計画を作成しております
E4: ・47行目以降のハイライト箇所に、別途算定した計画を転記ください | AD4: 26年3月期 | AE4: 26年3月期 | AF4: 26年3月期 | AG4: 26年3月期 | AH4: 26年3月期 | AI4: 26年3月期 | AJ4: 26年3月期 | AK4: 26年3月期 | AL4: 26年3月期 | AM4: 26年3月期 | AN4: 26年3月期 | AO4: 26年3月期 | AP4: 27年3月期 | AQ4: 27年3月期 | AR4: 27年3月期 | AS4: 27年3月期 | AT4: 27年3月期 | AU4: 27年3月期 | AV4: 27年3月期 | AW4: 27年3月期 | AX4: 27年3月期 | AY4: 27年3月期 | AZ4: 27年3月期 | BA4: 27年3月期 | BB4: 28年3月期 | BC4: 28年3月期 | BD4: 28年3月期 | BE4: 28年3月期 | BF4: 28年3月期 | BG4: 28年3月期 | BH4: 28年3月期 | BI4: 28年3月期 | BJ4: 28年3月期 | BK4: 28年3月期 | BL4: 28年3月期 | BM4: 28年3月期 | BN4: 29年3月期 | BO4: 29年3月期 | BP4: 29年3月期 | BQ4: 29年3月期 | BR4: 29年3月期 | BS4: 29年3月期 | BT4: 29年3月期 | BU4: 29年3月期 | BV4: 29年3月期 | BW4: 29年3月期 | BX4: 29年3月期 | BY4: 29年3月期 | BZ4: 30年3月期 | CA4: 30年3月期 | CB4: 30年3月期 | CC4: 30年3月期 | CD4: 30年3月期 | CE4: 30年3月期 | CF4: 30年3月期 | CG4: 30年3月期 | CH4: 30年3月期 | CI4: 30年3月期 | CJ4: 30年3月期 | CK4: 30年3月期
E5: ・28/3月期以降は年次となる場合は、年度の最終月に年間の数値を入力ください | AD5: 1H | AE5: 1H | AF5: 1H | AG5: 1H | AH5: 1H | AI5: 1H | AJ5: 2H | AK5: 2H | AL5: 2H | AM5: 2H | AN5: 2H | AO5: 2H | AP5: 1H | AQ5: 1H | AR5: 1H | AS5: 1H | AT5: 1H | AU5: 1H | AV5: 2H | AW5: 2H | AX5: 2H | AY5: 2H | AZ5: 2H | BA5: 2H | BB5: 1H | BC5: 1H | BD5: 1H | BE5: 1H | BF5: 1H | BG5: 1H | BH5: 2H | BI5: 2H | BJ5: 2H | BK5: 2H | BL5: 2H | BM5: 2H | BN5: 1H | BO5: 1H | BP5: 1H | BQ5: 1H | BR5: 1H | BS5: 1H | BT5: 2H | BU5: 2H | BV5: 2H | BW5: 2H | BX5: 2H | BY5: 2H | BZ5: 1H | CA5: 1H | CB5: 1H | CC5: 1H | CD5: 1H | CE5: 1H | CF5: 2H | CG5: 2H | CH5: 2H | CI5: 2H | CJ5: 2H | CK5: 2H
E6: ・”ウタイテ配賦額”は経営指導料を入力する箇所となりますのでご対応不要です | AD6: 1Q | AE6: 1Q | AF6: 1Q | AG6: 2Q | AH6: 2Q | AI6: 2Q | AJ6: 3Q | AK6: 3Q | AL6: 3Q | AM6: 4Q | AN6: 4Q | AO6: 4Q | AP6: 1Q | AQ6: 1Q | AR6: 1Q | AS6: 2Q | AT6: 2Q | AU6: 2Q | AV6: 3Q | AW6: 3Q | AX6: 3Q | AY6: 4Q | AZ6: 4Q | BA6: 4Q | BB6: 1Q | BC6: 1Q | BD6: 1Q | BE6: 2Q | BF6: 2Q | BG6: 2Q | BH6: 3Q | BI6: 3Q | BJ6: 3Q | BK6: 4Q | BL6: 4Q | BM6: 4Q | BN6: 1Q | BO6: 1Q | BP6: 1Q | BQ6: 2Q | BR6: 2Q | BS6: 2Q | BT6: 3Q | BU6: 3Q | BV6: 3Q | BW6: 4Q | BX6: 4Q | BY6: 4Q | BZ6: 1Q | CA6: 1Q | CB6: 1Q | CC6: 2Q | CD6: 2Q | CE6: 2Q | CF6: 3Q | CG6: 3Q | CH6: 3Q | CI6: 4Q | CJ6: 4Q | CK6: 4Q
AD7: 実績 | AE7: 実績 | AF7: 実績 | AG7: 実績 | AH7: 実績 | AI7: 実績 | AJ7: 実績 | AK7: 実績 | AL7: 実績 | AM7: 実績 | AN7: 実績 | AO7: 予算 | AP7: 実績 | AQ7: 予算 | AR7: 予算 | AS7: 予算 | AT7: 予算 | AU7: 予算 | AV7: 予算 | AW7: 予算 | AX7: 予算 | AY7: 予算 | AZ7: 予算 | BA7: 予算 | BB7: 予算 | BC7: 予算 | BD7: 予算 | BE7: 予算 | BF7: 予算 | BG7: 予算 | BH7: 予算 | BI7: 予算 | BJ7: 予算 | BK7: 予算 | BL7: 予算 | BM7: 予算 | BN7: 予算 | BO7: 予算 | BP7: 予算 | BQ7: 予算 | BR7: 予算 | BS7: 予算 | BT7: 予算 | BU7: 予算 | BV7: 予算 | BW7: 予算 | BX7: 予算 | BY7: 予算 | BZ7: 予算 | CA7: 予算 | CB7: 予算 | CC7: 予算 | CD7: 予算 | CE7: 予算 | CF7: 予算 | CG7: 予算 | CH7: 予算 | CI7: 予算 | CJ7: 予算 | CK7: 予算
H8: Sort | AD8: 25/4月 | AE8: 25/5月 | AF8: 25/6月 | AG8: 25/7月 | AH8: 25/8月 | AI8: 25/9月 | AJ8: 25/10月 | AK8: 25/11月 | AL8: 25/12月 | AM8: 26/1月 | AN8: 26/2月 | AO8: 26/3月 | AP8: 26/4月 | AQ8: 26/5月 | AR8: 26/6月 | AS8: 26/7月 | AT8: 26/8月 | AU8: 26/9月 | AV8: 26/10月 | AW8: 26/11月 | AX8: 26/12月 | AY8: 27/1月 | AZ8: 27/2月 | BA8: 27/3月 | BB8: 27/4月 | BC8: 27/5月 | BD8: 27/6月 | BE8: 27/7月 | BF8: 27/8月 | BG8: 27/9月 | BH8: 27/10月 | BI8: 27/11月 | BJ8: 27/12月 | BK8: 28/1月 | BL8: 28/2月 | BM8: 28/3月 | BN8: 28/4月 | BO8: 28/5月 | BP8: 28/6月 | BQ8: 28/7月 | BR8: 28/8月 | BS8: 28/9月 | BT8: 28/10月 | BU8: 28/11月 | BV8: 28/12月 | BW8: 29/1月 | BX8: 29/2月 | BY8: 29/3月 | BZ8: 29/4月 | CA8: 29/5月 | CB8: 29/6月 | CC8: 29/7月 | CD8: 29/8月 | CE8: 29/9月 | CF8: 29/10月 | CG8: 29/11月 | CH8: 29/12月 | CI8: 30/1月 | CJ8: 30/2月 | CK8: 30/3月 | CM8: 集計
A9: X | E9: 売上高 | F9: - | H9: 1 | I9: YOANI | J9: ALL | AP9: 0 | AQ9: 0 | AR9: 0 | AS9: 0 | AT9: 0 | AU9: 0 | AV9: 0 | AW9: 0 | AX9: 0 | AY9: 0 | AZ9: 0 | BA9: 0 | BB9: 0 | BC9: 0 | BD9: 0 | BE9: 0 | BF9: 0 | BG9: 0 | BH9: 0 | BI9: 0 | BJ9: 0 | BK9: 0 | BL9: 0 | BM9: 0 | BN9: 0 | BO9: 0 | BP9: 0 | BQ9: 0 | BR9: 0 | BS9: 0 | BT9: 0 | BU9: 0 | BV9: 0 | BW9: 0 | BX9: 0 | BY9: 0 | BZ9: 0 | CA9: 0 | CB9: 0 | CC9: 0 | CD9: 0 | CE9: 0 | CF9: 0 | CG9: 0 | CH9: 0 | CI9: 0 | CJ9: 0 | CK9: 0 | CM9: 売上高
E10: 変動費 | F10: 仕入高 | I10: YOANI | J10: ALL | AP10: 0 | AQ10: 0 | AR10: 0 | AS10: 0 | AT10: 0 | AU10: 0 | AV10: 0 | AW10: 0 | AX10: 0 | AY10: 0 | AZ10: 0 | BA10: 0 | BB10: 0 | BC10: 0 | BD10: 0 | BE10: 0 | BF10: 0 | BG10: 0 | BH10: 0 | BI10: 0 | BJ10: 0 | BK10: 0 | BL10: 0 | BM10: 0 | BN10: 0 | BO10: 0 | BP10: 0 | BQ10: 0 | BR10: 0 | BS10: 0 | BT10: 0 | BU10: 0 | BV10: 0 | BW10: 0 | BX10: 0 | BY10: 0 | BZ10: 0 | CA10: 0 | CB10: 0 | CC10: 0 | CD10: 0 | CE10: 0 | CF10: 0 | CG10: 0 | CH10: 0 | CI10: 0 | CJ10: 0 | CK10: 0 | CM10: 仕入高
E11: 変動費 | F11: 外注費 | I11: YOANI | J11: ALL | AP11: 0 | AQ11: 0 | AR11: 0 | AS11: 0 | AT11: 0 | AU11: 0 | AV11: 0 | AW11: 0 | AX11: 0 | AY11: 0 | AZ11: 0 | BA11: 0 | BB11: 0 | BC11: 0 | BD11: 0 | BE11: 0 | BF11: 0 | BG11: 0 | BH11: 0 | BI11: 0 | BJ11: 0 | BK11: 0 | BL11: 0 | BM11: 0 | BN11: 0 | BO11: 0 | BP11: 0 | BQ11: 0 | BR11: 0 | BS11: 0 | BT11: 0 | BU11: 0 | BV11: 0 | BW11: 0 | BX11: 0 | BY11: 0 | BZ11: 0 | CA11: 0 | CB11: 0 | CC11: 0 | CD11: 0 | CE11: 0 | CF11: 0 | CG11: 0 | CH11: 0 | CI11: 0 | CJ11: 0 | CK11: 0 | CM11: 外注費
E12: 変動費 | F12: 荷造運賃 | I12: YOANI | J12: ALL | AP12: 0 | AQ12: 0 | AR12: 0 | AS12: 0 | AT12: 0 | AU12: 0 | AV12: 0 | AW12: 0 | AX12: 0 | AY12: 0 | AZ12: 0 | BA12: 0 | BB12: 0 | BC12: 0 | BD12: 0 | BE12: 0 | BF12: 0 | BG12: 0 | BH12: 0 | BI12: 0 | BJ12: 0 | BK12: 0 | BL12: 0 | BM12: 0 | BN12: 0 | BO12: 0 | BP12: 0 | BQ12: 0 | BR12: 0 | BS12: 0 | BT12: 0 | BU12: 0 | BV12: 0 | BW12: 0 | BX12: 0 | BY12: 0 | BZ12: 0 | CA12: 0 | CB12: 0 | CC12: 0 | CD12: 0 | CE12: 0 | CF12: 0 | CG12: 0 | CH12: 0 | CI12: 0 | CJ12: 0 | CK12: 0 | CM12: 荷造運賃
E13: 変動費 | F13: 支払手数料 | I13: YOANI | J13: ALL | AP13: 0 | AQ13: 0 | AR13: 0 | AS13: 0 | AT13: 0 | AU13: 0 | AV13: 0 | AW13: 0 | AX13: 0 | AY13: 0 | AZ13: 0 | BA13: 0 | BB13: 0 | BC13: 0 | BD13: 0 | BE13: 0 | BF13: 0 | BG13: 0 | BH13: 0 | BI13: 0 | BJ13: 0 | BK13: 0 | BL13: 0 | BM13: 0 | BN13: 0 | BO13: 0 | BP13: 0 | BQ13: 0 | BR13: 0 | BS13: 0 | BT13: 0 | BU13: 0 | BV13: 0 | BW13: 0 | BX13: 0 | BY13: 0 | BZ13: 0 | CA13: 0 | CB13: 0 | CC13: 0 | CD13: 0 | CE13: 0 | CF13: 0 | CG13: 0 | CH13: 0 | CI13: 0 | CJ13: 0 | CK13: 0 | CM13: 支払手数料
E14: 変動費 | F14: 保険料 | I14: YOANI | J14: ALL | AP14: 0 | AQ14: 0 | AR14: 0 | AS14: 0 | AT14: 0 | AU14: 0 | AV14: 0 | AW14: 0 | AX14: 0 | AY14: 0 | AZ14: 0 | BA14: 0 | BB14: 0 | BC14: 0 | BD14: 0 | BE14: 0 | BF14: 0 | BG14: 0 | BH14: 0 | BI14: 0 | BJ14: 0 | BK14: 0 | BL14: 0 | BM14: 0 | BN14: 0 | BO14: 0 | BP14: 0 | BQ14: 0 | BR14: 0 | BS14: 0 | BT14: 0 | BU14: 0 | BV14: 0 | BW14: 0 | BX14: 0 | BY14: 0 | BZ14: 0 | CA14: 0 | CB14: 0 | CC14: 0 | CD14: 0 | CE14: 0 | CF14: 0 | CG14: 0 | CH14: 0 | CI14: 0 | CJ14: 0 | CK14: 0 | CM14: 保険料
E15: 準変動費 | F15: 広告宣伝費 | I15: YOANI | J15: ALL | AP15: 0 | AQ15: 0 | AR15: 0 | AS15: 0 | AT15: 0 | AU15: 0 | AV15: 0 | AW15: 0 | AX15: 0 | AY15: 0 | AZ15: 0 | BA15: 0 | BB15: 0 | BC15: 0 | BD15: 0 | BE15: 0 | BF15: 0 | BG15: 0 | BH15: 0 | BI15: 0 | BJ15: 0 | BK15: 0 | BL15: 0 | BM15: 0 | BN15: 0 | BO15: 0 | BP15: 0 | BQ15: 0 | BR15: 0 | BS15: 0 | BT15: 0 | BU15: 0 | BV15: 0 | BW15: 0 | BX15: 0 | BY15: 0 | BZ15: 0 | CA15: 0 | CB15: 0 | CC15: 0 | CD15: 0 | CE15: 0 | CF15: 0 | CG15: 0 | CH15: 0 | CI15: 0 | CJ15: 0 | CK15: 0 | CM15: 広告宣伝費
E16: 準変動費 | F16: その他 | I16: YOANI | J16: ALL | AP16: 0 | AQ16: 0 | AR16: 0 | AS16: 0 | AT16: 0 | AU16: 0 | AV16: 0 | AW16: 0 | AX16: 0 | AY16: 0 | AZ16: 0 | BA16: 0 | BB16: 0 | BC16: 0 | BD16: 0 | BE16: 0 | BF16: 0 | BG16: 0 | BH16: 0 | BI16: 0 | BJ16: 0 | BK16: 0 | BL16: 0 | BM16: 0 | BN16: 0 | BO16: 0 | BP16: 0 | BQ16: 0 | BR16: 0 | BS16: 0 | BT16: 0 | BU16: 0 | BV16: 0 | BW16: 0 | BX16: 0 | BY16: 0 | BZ16: 0 | CA16: 0 | CB16: 0 | CC16: 0 | CD16: 0 | CE16: 0 | CF16: 0 | CG16: 0 | CH16: 0 | CI16: 0 | CJ16: 0 | CK16: 0 | CM16: その他
E17: 準変動費 | F17: タレント報酬 | I17: YOANI | J17: ALL | AP17: 0 | AQ17: 0 | AR17: 0 | AS17: 0 | AT17: 0 | AU17: 0 | AV17: 0 | AW17: 0 | AX17: 0 | AY17: 0 | AZ17: 0 | BA17: 0 | BB17: 0 | BC17: 0 | BD17: 0 | BE17: 0 | BF17: 0 | BG17: 0 | BH17: 0 | BI17: 0 | BJ17: 0 | BK17: 0 | BL17: 0 | BM17: 0 | BN17: 0 | BO17: 0 | BP17: 0 | BQ17: 0 | BR17: 0 | BS17: 0 | BT17: 0 | BU17: 0 | BV17: 0 | BW17: 0 | BX17: 0 | BY17: 0 | BZ17: 0 | CA17: 0 | CB17: 0 | CC17: 0 | CD17: 0 | CE17: 0 | CF17: 0 | CG17: 0 | CH17: 0 | CI17: 0 | CJ17: 0 | CK17: 0 | CM17: タレント報酬
E18: 準変動費 | F18: 人件費 | I18: YOANI | J18: ALL | AP18: 0 | AQ18: 0 | AR18: 0 | AS18: 0 | AT18: 0 | AU18: 0 | AV18: 0 | AW18: 0 | AX18: 0 | AY18: 0 | AZ18: 0 | BA18: 0 | BB18: 0 | BC18: 0 | BD18: 0 | BE18: 0 | BF18: 0 | BG18: 0 | BH18: 0 | BI18: 0 | BJ18: 0 | BK18: 0 | BL18: 0 | BM18: 0 | BN18: 0 | BO18: 0 | BP18: 0 | BQ18: 0 | BR18: 0 | BS18: 0 | BT18: 0 | BU18: 0 | BV18: 0 | BW18: 0 | BX18: 0 | BY18: 0 | BZ18: 0 | CA18: 0 | CB18: 0 | CC18: 0 | CD18: 0 | CE18: 0 | CF18: 0 | CG18: 0 | CH18: 0 | CI18: 0 | CJ18: 0 | CK18: 0 | CM18: 人件費
E19: 準変動費 | F19: 採用教育費 | I19: YOANI | J19: ALL | AP19: 0 | AQ19: 0 | AR19: 0 | AS19: 0 | AT19: 0 | AU19: 0 | AV19: 0 | AW19: 0 | AX19: 0 | AY19: 0 | AZ19: 0 | BA19: 0 | BB19: 0 | BC19: 0 | BD19: 0 | BE19: 0 | BF19: 0 | BG19: 0 | BH19: 0 | BI19: 0 | BJ19: 0 | BK19: 0 | BL19: 0 | BM19: 0 | BN19: 0 | BO19: 0 | BP19: 0 | BQ19: 0 | BR19: 0 | BS19: 0 | BT19: 0 | BU19: 0 | BV19: 0 | BW19: 0 | BX19: 0 | BY19: 0 | BZ19: 0 | CA19: 0 | CB19: 0 | CC19: 0 | CD19: 0 | CE19: 0 | CF19: 0 | CG19: 0 | CH19: 0 | CI19: 0 | CJ19: 0 | CK19: 0 | CM19: 採用教育費
E20: 固定費 | F20: 共通費配賦 | I20: YOANI | J20: ALL | AP20: 0 | AQ20: 0 | AR20: 0 | AS20: 0 | AT20: 0 | AU20: 0 | AV20: 0 | AW20: 0 | AX20: 0 | AY20: 0 | AZ20: 0 | BA20: 0 | BB20: 0 | BC20: 0 | BD20: 0 | BE20: 0 | BF20: 0 | BG20: 0 | BH20: 0 | BI20: 0 | BJ20: 0 | BK20: 0 | BL20: 0 | BM20: 0 | BN20: 0 | BO20: 0 | BP20: 0 | BQ20: 0 | BR20: 0 | BS20: 0 | BT20: 0 | BU20: 0 | BV20: 0 | BW20: 0 | BX20: 0 | BY20: 0 | BZ20: 0 | CA20: 0 | CB20: 0 | CC20: 0 | CD20: 0 | CE20: 0 | CF20: 0 | CG20: 0 | CH20: 0 | CI20: 0 | CJ20: 0 | CK20: 0 | CM20: 共通費配賦
E21: 固定費 | F21: 地代家賃 | I21: YOANI | J21: ALL | AP21: 0 | AQ21: 0 | AR21: 0 | AS21: 0 | AT21: 0 | AU21: 0 | AV21: 0 | AW21: 0 | AX21: 0 | AY21: 0 | AZ21: 0 | BA21: 0 | BB21: 0 | BC21: 0 | BD21: 0 | BE21: 0 | BF21: 0 | BG21: 0 | BH21: 0 | BI21: 0 | BJ21: 0 | BK21: 0 | BL21: 0 | BM21: 0 | BN21: 0 | BO21: 0 | BP21: 0 | BQ21: 0 | BR21: 0 | BS21: 0 | BT21: 0 | BU21: 0 | BV21: 0 | BW21: 0 | BX21: 0 | BY21: 0 | BZ21: 0 | CA21: 0 | CB21: 0 | CC21: 0 | CD21: 0 | CE21: 0 | CF21: 0 | CG21: 0 | CH21: 0 | CI21: 0 | CJ21: 0 | CK21: 0 | CM21: 地代家賃
... E34: 固定費 | F34: ウタイテ配賦額 | I34: YOANI | J34: ALL | AP34: 0 | AQ34: 0 | AR34: 0 | AS34: 0 | AT34: 0 | AU34: 0 | AV34: 0 | AW34: 0 | AX34: 0 | AY34: 0 | AZ34: 0 | BA34: 0 | BB34: 0 | BC34: 0 | BD34: 0 | BE34: 0 | BF34: 0 | BG34: 0 | BH34: 0 | BI34: 0 | BJ34: 0 | BK34: 0 | BL34: 0 | BM34: 0 | BN34: 0 | BO34: 0 | BP34: 0 | BQ34: 0 | BR34: 0 | BS34: 0 | BT34: 0 | BU34: 0 | BV34: 0 | BW34: 0 | BX34: 0 | BY34: 0 | BZ34: 0 | CA34: 0 | CB34: 0 | CC34: 0 | CD34: 0 | CE34: 0 | CF34: 0 | CG34: 0 | CH34: 0 | CI34: 0 | CJ34: 0 | CK34: 0 | CM34: ウタイテ配賦額
E36: 営業利益 | H36: 1 | I36: YOANI | J36: ALL | AD36: 0 | AE36: 0 | AF36: 0 | AG36: 0 | AH36: 0 | AI36: 0 | AJ36: 0 | AK36: 0 | AL36: 0 | AM36: 0 | AN36: 0 | AO36: 0 | AP36: 0 | AQ36: 0 | AR36: 0 | AS36: 0 | AT36: 0 | AU36: 0 | AV36: 0 | AW36: 0 | AX36: 0 | AY36: 0 | AZ36: 0 | BA36: 0 | BB36: 0 | BC36: 0 | BD36: 0 | BE36: 0 | BF36: 0 | BG36: 0 | BH36: 0 | BI36: 0 | BJ36: 0 | BK36: 0 | BL36: 0 | BM36: 0 | BN36: 0 | BO36: 0 | BP36: 0 | BQ36: 0 | BR36: 0 | BS36: 0 | BT36: 0 | BU36: 0 | BV36: 0 | BW36: 0 | BX36: 0 | BY36: 0 | BZ36: 0 | CA36: 0 | CB36: 0 | CC36: 0 | CD36: 0 | CE36: 0 | CF36: 0 | CG36: 0 | CH36: 0 | CI36: 0 | CJ36: 0 | CK36: 0
E37: 営業外収益 | F37: - | I37: YOANI | J37: ALL
E38: 営業外収益 | F38: - | I38: YOANI | J38: ALL
E39: 特別利益 | F39: - | I39: YOANI | J39: ALL
E40: 特別損失 | F40: - | I40: YOANI | J40: ALL
E41: 法人税等 | F41: - | I41: YOANI | J41: ALL
E42: 法人税等調整額 | F42: - | I42: YOANI | J42: ALL
E43: 当期純利益 | I43: YOANI | J43: ALL | AP43: 0 | AQ43: 0 | AR43: 0 | AS43: 0 | AT43: 0 | AU43: 0 | AV43: 0 | AW43: 0 | AX43: 0 | AY43: 0 | AZ43: 0 | BA43: 0 | BB43: 0 | BC43: 0 | BD43: 0 | BE43: 0 | BF43: 0 | BG43: 0 | BH43: 0 | BI43: 0 | BJ43: 0 | BK43: 0 | BL43: 0 | BM43: 0 | BN43: 0 | BO43: 0 | BP43: 0 | BQ43: 0 | BR43: 0 | BS43: 0 | BT43: 0 | BU43: 0 | BV43: 0 | BW43: 0 | BX43: 0 | BY43: 0 | BZ43: 0 | CA43: 0 | CB43: 0 | CC43: 0 | CD43: 0 | CE43: 0 | CF43: 0 | CG43: 0 | CH43: 0 | CI43: 0 | CJ43: 0 | CK43: 0
B44: 補助列 | C44: ②マスタ結びつけ | D44: ①
H46: 1
B47: {=XLOOKUP(D47, 'マスタ'!$C$2:$C$1000, 'マスタ'!$D$2:$D$1000, "マスタ未登録")} -> 売上高 | C47: =IF(AND(D47<>"", COUNTIF('マスタ'!$C:$C, D47)=0), "マスタ未登録", "") | D47: =F47 -> 売上高 | E47: 売上高 | F47: 売上高 | H47: 1 | I47: YOANI | J47: 教育 | AD47: 296871389 | AE47: 272456691 | AF47: 267326019 | AG47: 265471022 | AH47: 266436263 | AI47: 271947067 | AJ47: 264563154 | AK47: 264405743 | AL47: 271514056 | AM47: 264967685 | AN47: 265297276 | AO47: 288600861 | AP47: 274897527 | AQ47: 274492845 | AR47: 264523861 | AS47: 255898325 | AT47: 256871049 | AU47: 264602714 | AV47: 253501668 | AW47: 254037604 | AX47: 255058656 | AY47: 254518036 | AZ47: 254893626 | BA47: 272121852 | CM47: 売上高
B48: {=XLOOKUP(D48, 'マスタ'!$C$2:$C$1000, 'マスタ'!$D$2:$D$1000, "マスタ未登録")} -> 当期商品仕入高 | C48: =IF(AND(D48<>"", COUNTIF('マスタ'!$C:$C, D48)=0), "マスタ未登録", "") | D48: =F48 -> 仕入高 | E48: 変動費 | F48: 仕入高 | I48: YOANI | J48: 教育 | AD48: -18163675 | AE48: -512673 | AF48: -570122 | AG48: -521683 | AH48: -1096110 | AI48: -427596 | AJ48: -466100 | AK48: 0 | AL48: 0 | AM48: -2816523 | AN48: -12699 | AO48: -4241810 | AP48: -20886815 | AQ48: -110000 | AR48: -280000 | AS48: -922200 | AT48: -843000 | AU48: -1626346 | AV48: -4000000 | AW48: 0 | AX48: -2000000 | AY48: 0 | AZ48: 0 | BA48: 0 | CM48: 仕入高
B49: {=XLOOKUP(D49, 'マスタ'!$C$2:$C$1000, 'マスタ'!$D$2:$D$1000, "マスタ未登録")} -> 外注費 | C49: =IF(AND(D49<>"", COUNTIF('マスタ'!$C:$C, D49)=0), "マスタ未登録", "") | D49: =F49 -> 外注費 | E49: 変動費 | F49: 外注費 | I49: YOANI | J49: 教育 | AD49: -25458188 | AE49: -32906723 | AF49: -32397971 | AG49: -28112283 | AH49: -17214188 | AI49: -25815330 | AJ49: -34137291 | AK49: -33442240 | AL49: -30494279 | AM49: -24470263 | AN49: -25435271 | AO49: -16211713 | AP49: -26185502 | AQ49: -25778170 | AR49: -28177410 | AS49: -25677255 | AT49: -19180474 | AU49: -21240287 | AV49: -28291389 | AW49: -28026400 | AX49: -28658094 | AY49: -21446984 | AZ49: -23243028 | BA49: -10798206 | CM49: 外注費
B50: {=XLOOKUP(D50, 'マスタ'!$C$2:$C$1000, 'マスタ'!$D$2:$D$1000, "マスタ未登録")} -> 荷造運賃 | C50: =IF(AND(D50<>"", COUNTIF('マスタ'!$C:$C, D50)=0), "マスタ未登録", "") | D50: =F50 -> 荷造運賃 | E50: 変動費 | F50: 荷造運賃 | I50: YOANI | J50: 教育 | AD50: -280865 | AE50: -266998 | AF50: -188754 | AG50: -343183 | AH50: -153943 | AI50: -146868 | AJ50: -150097 | AK50: -99671 | AL50: -211161 | AM50: -323779 | AN50: -272691 | AO50: -409224 | AP50: -247405 | AQ50: -285180 | AR50: -218969 | AS50: -237399 | AT50: -152512 | AU50: -204805 | AV50: -146347 | AW50: -130869 | AX50: -215970 | AY50: -284828 | AZ50: -203170 | BA50: -197634 | CM50: 荷造運賃
B51: {=XLOOKUP(D51, 'マスタ'!$C$2:$C$1000, 'マスタ'!$D$2:$D$1000, "マスタ未登録")} -> 支払手数料 | C51: =IF(AND(D51<>"", COUNTIF('マスタ'!$C:$C, D51)=0), "マスタ未登録", "") | D51: =F51 -> 支払手数料 | E51: 変動費 | F51: 支払手数料 | I51: YOANI | J51: 教育 | AD51: -262935 | AE51: -286121 | AF51: -254147 | AG51: -230125 | AH51: -315764 | AI51: -320245 | AJ51: -229760 | AK51: -1728704 | AL51: -2913841 | AM51: 1031916 | AN51: -445982 | AO51: 941363 | AP51: -255162 | AQ51: -224550 | AR51: -224550 | AS51: -224550 | AT51: -224550 | AU51: -224550 | AV51: -224550 | AW51: -224550 | AX51: -224550 | AY51: -224550 | AZ51: -224550 | BA51: -224550 | CM51: 支払手数料
B52: {=XLOOKUP(D52, 'マスタ'!$C$2:$C$1000, 'マスタ'!$D$2:$D$1000, "マスタ未登録")} -> 保険料 | C52: =IF(AND(D52<>"", COUNTIF('マスタ'!$C:$C, D52)=0), "マスタ未登録", "") | D52: =F52 -> 保険料 | E52: 変動費 | F52: 保険料 | I52: YOANI | J52: 教育 | AD52: -1039587 | AE52: -1038723 | AF52: -1039583 | AG52: -1065604 | AH52: -1045113 | AI52: -1045603 | AJ52: -1287943 | AK52: -1057233 | AL52: -1169973 | AM52: -1057583 | AN52: -1039583 | AO52: -1039583 | AP52: -1039587 | AQ52: -1039583 | AR52: -1039583 | AS52: -1039583 | AT52: -1039583 | AU52: -1039583 | AV52: -1039583 | AW52: -1039583 | AX52: -1039583 | AY52: -1039583 | AZ52: -1039583 | BA52: -1039583 | CM52: 保険料
B53: {=XLOOKUP(D53, 'マスタ'!$C$2:$C$1000, 'マスタ'!$D$2:$D$1000, "マスタ未登録")} -> 広告宣伝費 | C53: =IF(AND(D53<>"", COUNTIF('マスタ'!$C:$C, D53)=0), "マスタ未登録", "") | D53: =F53 -> 広告宣伝費 | E53: 準変動費 | F53: 広告宣伝費 | I53: YOANI | J53: 教育 | AD53: -63471142 | AE53: -62040319 | AF53: -75533817 | AG53: -88887280 | AH53: -80417496 | AI53: -48528184 | AJ53: -52450852 | AK53: -44125455 | AL53: -44020295 | AM53: -52143004 | AN53: -122333431 | AO53: -79537168 | AP53: -48303471 | AQ53: -41723670 | AR53: -41910955 | AS53: -45367005 | AT53: -37452174 | AU53: -37123992 | AV53: -35568128 | AW53: -36633492 | AX53: -38640879 | AY53: -40595115 | AZ53: -59367818 | BA53: -24117200 | CM53: 広告宣伝費
B54: {=XLOOKUP(D54, 'マスタ'!$C$2:$C$1000, 'マスタ'!$D$2:$D$1000, "マスタ未登録")} -> その他 | C54: =IF(AND(D54<>"", COUNTIF('マスタ'!$C:$C, D54)=0), "マスタ未登録", "") | D54: =F54 -> その他（変） | E54: 準変動費 | F54: その他（変） | I54: YOANI | J54: 教育 | AD54: 0 | AE54: 0 | AF54: 0 | AG54: 0 | AH54: 0 | AI54: 0 | AJ54: 0 | AK54: 0 | AL54: 0 | AM54: 0 | AN54: 0 | AO54: 0 | AP54: 0 | AQ54: 0 | AR54: 0 | AS54: 0 | AT54: 0 | AU54: 0 | AV54: 0 | AW54: 0 | AX54: 0 | AY54: 0 | AZ54: 0 | BA54: 0 | CM54: その他_準変動
...

Sheet FoC_PL
D1: 月次推移：損益計算書_ForCreators株式会社（期間：2026年04月〜2027年03月、表示単位：円）
J2: 46113 | K2: 46143 | L2: 46174 | M2: 46204 | N2: 46235 | O2: 46266 | P2: 46296 | Q2: 46327 | R2: 46357 | S2: 46388 | T2: 46419 | U2: 46447 | V2: 期間累計
D3: 売上高
A4: {=XLOOKUP(C4, 'マスタ'!$C$2:$C$312, 'マスタ'!$D$2:$D$312, "マスタ未登録")} -> 売上高 | B4: =IF(AND(C4<>"", COUNTIF('マスタ'!$C:$C, C4)=0), "マスタ未登録", "") | C4: =D4&D109&E4&F4&G4&H4 -> 売上高 | E4: 売上高 | J4: 21265200 | K4: 32272288 | L4: 0 | M4: 0 | N4: 0 | O4: 0 | P4: 0 | Q4: 0 | R4: 0 | S4: 0 | T4: 0 | U4: 0 | V4: 53537488
A5: {=XLOOKUP(C5, 'マスタ'!$C$2:$C$312, 'マスタ'!$D$2:$D$312, "マスタ未登録")} -> マスタ未登録 | B5: =IF(AND(C5<>"", COUNTIF('マスタ'!$C:$C, C5)=0), "マスタ未登録", "") -> マスタ未登録 | C5: =D5&D110&E5&F5&G5&H5 -> 売上高 計 | D5: 売上高 計 | J5: 21265200 | K5: 32272288 | L5: 0 | M5: 0 | N5: 0 | O5: 0 | P5: 0 | Q5: 0 | R5: 0 | S5: 0 | T5: 0 | U5: 0 | V5: 53537488
A6: {=XLOOKUP(C6, 'マスタ'!$C$2:$C$312, 'マスタ'!$D$2:$D$312, "マスタ未登録")} -> マスタ未登録 | B6: =IF(AND(C6<>"", COUNTIF('マスタ'!$C:$C, C6)=0), "マスタ未登録", "") -> マスタ未登録 | C6: =D6&D111&E6&F6&G6&H6 -> 売上原価 | E6: 売上原価
A7: {=XLOOKUP(C7, 'マスタ'!$C$2:$C$312, 'マスタ'!$D$2:$D$312, "マスタ未登録")} -> マスタ未登録 | B7: =IF(AND(C7<>"", COUNTIF('マスタ'!$C:$C, C7)=0), "マスタ未登録", "") -> マスタ未登録 | C7: =D7&D112&E7&F7&G7&H7 -> 売上原価 | E7: 売上原価 | J7: 13187465 | K7: 15954741 | L7: 684688 | M7: 461927 | N7: 461927 | O7: 461927 | P7: 461927 | Q7: 461927 | R7: 461927 | S7: 461927 | T7: 461927 | U7: 461957 | V7: 33984267
A8: {=XLOOKUP(C8, 'マスタ'!$C$2:$C$312, 'マスタ'!$D$2:$D$312, "マスタ未登録")} -> 期首商品棚卸高 | B8: =IF(AND(C8<>"", COUNTIF('マスタ'!$C:$C, C8)=0), "マスタ未登録", "") | C8: =D8&D113&E8&F8&G8&H8 -> 期首商品棚卸 | G8: 期首商品棚卸 | J8: 0 | K8: 0 | L8: 0 | M8: 0 | N8: 0 | O8: 0 | P8: 0 | Q8: 0 | R8: 0 | S8: 0 | T8: 0 | U8: 0 | V8: 0
A9: {=XLOOKUP(C9, 'マスタ'!$C$2:$C$312, 'マスタ'!$D$2:$D$312, "マスタ未登録")} -> 当期商品仕入高 | B9: =IF(AND(C9<>"", COUNTIF('マスタ'!$C:$C, C9)=0), "マスタ未登録", "") | C9: =D9&D114&E9&F9&G9&H9 -> 当期商品仕入 | G9: 当期商品仕入 | J9: 13187465 | K9: 15954741 | L9: 684688 | M9: 461927 | N9: 461927 | O9: 461927 | P9: 461927 | Q9: 461927 | R9: 461927 | S9: 461927 | T9: 461927 | U9: 461957 | V9: 33984267
A10: {=XLOOKUP(C10, 'マスタ'!$C$2:$C$312, 'マスタ'!$D$2:$D$312, "マスタ未登録")} -> 当期商品仕入高 | B10: =IF(AND(C10<>"", COUNTIF('マスタ'!$C:$C, C10)=0), "マスタ未登録", "") | C10: =D10&D115&E10&F10&G10&H10 -> 給料手当(原) | H10: 給料手当(原) | J10: 2258594 | K10: 2555829 | L10: 0 | M10: 0 | N10: 0 | O10: 0 | P10: 0 | Q10: 0 | R10: 0 | S10: 0 | T10: 0 | U10: 0 | V10: 4814423
A11: {=XLOOKUP(C11, 'マスタ'!$C$2:$C$312, 'マスタ'!$D$2:$D$312, "マスタ未登録")} -> 当期商品仕入高 | B11: =IF(AND(C11<>"", COUNTIF('マスタ'!$C:$C, C11)=0), "マスタ未登録", "") | C11: =D11&D116&E11&F11&G11&H11 -> 法定福利費(原) | H11: 法定福利費(原) | J11: 441611 | K11: 484872 | L11: 0 | M11: 0 | N11: 0 | O11: 0 | P11: 0 | Q11: 0 | R11: 0 | S11: 0 | T11: 0 | U11: 0 | V11: 926483
A12: {=XLOOKUP(C12, 'マスタ'!$C$2:$C$312, 'マスタ'!$D$2:$D$312, "マスタ未登録")} -> 当期商品仕入高 | B12: =IF(AND(C12<>"", COUNTIF('マスタ'!$C:$C, C12)=0), "マスタ未登録", "") | C12: =D12&D117&E12&F12&G12&H12 -> 外注費(原) | H12: 外注費(原) | J12: 9032770 | K12: 11131450 | L12: 0 | M12: 0 | N12: 0 | O12: 0 | P12: 0 | Q12: 0 | R12: 0 | S12: 0 | T12: 0 | U12: 0 | V12: 20164220
A13: {=XLOOKUP(C13, 'マスタ'!$C$2:$C$312, 'マスタ'!$D$2:$D$312, "マスタ未登録")} -> 当期商品仕入高 | B13: =IF(AND(C13<>"", COUNTIF('マスタ'!$C:$C, C13)=0), "マスタ未登録", "") | C13: =D13&D118&E13&F13&G13&H13 -> 業務委託費(原) | H13: 業務委託費(原) | J13: 595037 | K13: 904952 | L13: 0 | M13: 0 | N13: 0 | O13: 0 | P13: 0 | Q13: 0 | R13: 0 | S13: 0 | T13: 0 | U13: 0 | V13: 1499989
A14: {=XLOOKUP(C14, 'マスタ'!$C$2:$C$312, 'マスタ'!$D$2:$D$312, "マスタ未登録")} -> 当期商品仕入高 | B14: =IF(AND(C14<>"", COUNTIF('マスタ'!$C:$C, C14)=0), "マスタ未登録", "") | C14: =D14&D119&E14&F14&G14&H14 -> 旅費交通費(原) | H14: 旅費交通費(原) | J14: 100628 | K14: 141651 | L14: 0 | M14: 0 | N14: 0 | O14: 0 | P14: 0 | Q14: 0 | R14: 0 | S14: 0 | T14: 0 | U14: 0 | V14: 242279
A15: {=XLOOKUP(C15, 'マスタ'!$C$2:$C$312, 'マスタ'!$D$2:$D$312, "マスタ未登録")} -> 当期商品仕入高 | B15: =IF(AND(C15<>"", COUNTIF('マスタ'!$C:$C, C15)=0), "マスタ未登録", "") | C15: =D15&D120&E15&F15&G15&H15 -> 消耗品費(原) | H15: 消耗品費(原) | J15: 537 | K15: 0 | L15: 0 | M15: 0 | N15: 0 | O15: 0 | P15: 0 | Q15: 0 | R15: 0 | S15: 0 | T15: 0 | U15: 0 | V15: 537
A16: {=XLOOKUP(C16, 'マスタ'!$C$2:$C$312, 'マスタ'!$D$2:$D$312, "マスタ未登録")} -> 当期商品仕入高 | B16: =IF(AND(C16<>"", COUNTIF('マスタ'!$C:$C, C16)=0), "マスタ未登録", "") | C16: =D16&D121&E16&F16&G16&H16 -> 通信費(原) | H16: 通信費(原) | J16: 296361 | K16: 274060 | L16: 222761 | M16: 0 | N16: 0 | O16: 0 | P16: 0 | Q16: 0 | R16: 0 | S16: 0 | T16: 0 | U16: 0 | V16: 793182
A17: {=XLOOKUP(C17, 'マスタ'!$C$2:$C$312, 'マスタ'!$D$2:$D$312, "マスタ未登録")} -> 当期商品仕入高 | B17: =IF(AND(C17<>"", COUNTIF('マスタ'!$C:$C, C17)=0), "マスタ未登録", "") | C17: =D17&D122&E17&F17&G17&H17 -> 減価償却費(原) | H17: 減価償却費(原) | J17: 461927 | K17: 461927 | L17: 461927 | M17: 461927 | N17: 461927 | O17: 461927 | P17: 461927 | Q17: 461927 | R17: 461927 | S17: 461927 | T17: 461927 | U17: 461957 | V17: 5543154
A18: {=XLOOKUP(C18, 'マスタ'!$C$2:$C$312, 'マスタ'!$D$2:$D$312, "マスタ未登録")} -> 他勘定振替高 | B18: =IF(AND(C18<>"", COUNTIF('マスタ'!$C:$C, C18)=0), "マスタ未登録", "") | C18: =D18&D123&E18&F18&G18&H18 -> 他勘定振替高(商) | G18: 他勘定振替高(商) | J18: 0 | K18: 0 | L18: 0 | M18: 0 | N18: 0 | O18: 0 | P18: 0 | Q18: 0 | R18: 0 | S18: 0 | T18: 0 | U18: 0 | V18: 0
A19: {=XLOOKUP(C19, 'マスタ'!$C$2:$C$312, 'マスタ'!$D$2:$D$312, "マスタ未登録")} -> 期末商品棚卸高 | B19: =IF(AND(C19<>"", COUNTIF('マスタ'!$C:$C, C19)=0), "マスタ未登録", "") | C19: =D19&D124&E19&F19&G19&H19 -> 期末商品棚卸 | G19: 期末商品棚卸 | J19: 0 | K19: 0 | L19: 0 | M19: 0 | N19: 0 | O19: 0 | P19: 0 | Q19: 0 | R19: 0 | S19: 0 | T19: 0 | U19: 0 | V19: 0
A20: {=XLOOKUP(C20, 'マスタ'!$C$2:$C$312, 'マスタ'!$D$2:$D$312, "マスタ未登録")} -> マスタ未登録 | B20: =IF(AND(C20<>"", COUNTIF('マスタ'!$C:$C, C20)=0), "マスタ未登録", "") -> マスタ未登録 | C20: =D20&D125&E20&F20&G20&H20 -> 商品売上原価 | F20: 商品売上原価 | J20: 13187465 | K20: 15954741 | L20: 684688 | M20: 461927 | N20: 461927 | O20: 461927 | P20: 461927 | Q20: 461927 | R20: 461927 | S20: 461927 | T20: 461927 | U20: 461957 | V20: 33984267
A21: {=XLOOKUP(C21, 'マスタ'!$C$2:$C$312, 'マスタ'!$D$2:$D$312, "マスタ未登録")} -> マスタ未登録 | B21: =IF(AND(C21<>"", COUNTIF('マスタ'!$C:$C, C21)=0), "マスタ未登録", "") -> マスタ未登録 | C21: =D21&D126&E21&F21&G21&H21 -> 売上総損益金額 | D21: 売上総損益金額 | J21: 8077735 | K21: 16317547 | L21: -684688 | M21: -461927 | N21: -461927 | O21: -461927 | P21: -461927 | Q21: -461927 | R21: -461927 | S21: -461927 | T21: -461927 | U21: -461957 | V21: 19553221
A22: {=XLOOKUP(C22, 'マスタ'!$C$2:$C$312, 'マスタ'!$D$2:$D$312, "マスタ未登録")} -> マスタ未登録 | B22: =IF(AND(C22<>"", COUNTIF('マスタ'!$C:$C, C22)=0), "マスタ未登録", "") -> マスタ未登録 | C22: =D22&D127&E22&F22&G22&H22 -> 販売管理費 | E22: 販売管理費
A23: {=XLOOKUP(C23, 'マスタ'!$C$2:$C$312, 'マスタ'!$D$2:$D$312, "マスタ未登録")} -> 役員報酬 | B23: =IF(AND(C23<>"", COUNTIF('マスタ'!$C:$C, C23)=0), "マスタ未登録", "") | C23: =D23&D128&E23&F23&G23&H23 -> 役員報酬 | F23: 役員報酬 | J23: 1200000 | K23: 1200000 | L23: 0 | M23: 0 | N23: 0 | O23: 0 | P23: 0 | Q23: 0 | R23: 0 | S23: 0 | T23: 0 | U23: 0 | V23: 2400000
A24: {=XLOOKUP(C24, 'マスタ'!$C$2:$C$312, 'マスタ'!$D$2:$D$312, "マスタ未登録")} -> 採用教育費 | B24: =IF(AND(C24<>"", COUNTIF('マスタ'!$C:$C, C24)=0), "マスタ未登録", "") | C24: =D24&D129&E24&F24&G24&H24 -> 採用教育費 | F24: 採用教育費 | J24: 138000 | K24: 55000 | L24: 55000 | M24: 55000 | N24: 55000 | O24: 55000 | P24: 55000 | Q24: 55000 | R24: 55000 | S24: 55000 | T24: 55000 | U24: 55000 | V24: 743000
A25: {=XLOOKUP(C25, 'マスタ'!$C$2:$C$312, 'マスタ'!$D$2:$D$312, "マスタ未登録")} -> 業務委託費 | B25: =IF(AND(C25<>"", COUNTIF('マスタ'!$C:$C, C25)=0), "マスタ未登録", "") | C25: =D25&D130&E25&F25&G25&H25 -> 業務委託費 | F25: 業務委託費 | J25: 250420 | K25: 454055 | L25: 0 | M25: 0 | N25: 0 | O25: 0 | P25: 0 | Q25: 0 | R25: 0 | S25: 0 | T25: 0 | U25: 0 | V25: 704475
A26: {=XLOOKUP(C26, 'マスタ'!$C$2:$C$312, 'マスタ'!$D$2:$D$312, "マスタ未登録")} -> 外注費 | B26: =IF(AND(C26<>"", COUNTIF('マスタ'!$C:$C, C26)=0), "マスタ未登録", "") | C26: =D26&D131&E26&F26&G26&H26 -> 外注費 | F26: 外注費 | J26: -47 | K26: 0 | L26: 0 | M26: 0 | N26: 0 | O26: 0 | P26: 0 | Q26: 0 | R26: 0 | S26: 0 | T26: 0 | U26: 0 | V26: -47
A27: {=XLOOKUP(C27, 'マスタ'!$C$2:$C$312, 'マスタ'!$D$2:$D$312, "マスタ未登録")} -> 広告宣伝費 | B27: =IF(AND(C27<>"", COUNTIF('マスタ'!$C:$C, C27)=0), "マスタ未登録", "") | C27: =D27&D132&E27&F27&G27&H27 -> 広告宣伝費 | F27: 広告宣伝費 | J27: 23260 | K27: 15260 | L27: 0 | M27: 0 | N27: 0 | O27: 0 | P27: 0 | Q27: 0 | R27: 0 | S27: 0 | T27: 0 | U27: 0 | V27: 38520
A28: {=XLOOKUP(C28, 'マスタ'!$C$2:$C$312, 'マスタ'!$D$2:$D$312, "マスタ未登録")} -> 接待交際費 | B28: =IF(AND(C28<>"", COUNTIF('マスタ'!$C:$C, C28)=0), "マスタ未登録", "") | C28: =D28&D133&E28&F28&G28&H28 -> 交際費 | F28: 交際費 | J28: 124321 | K28: 34454 | L28: 0 | M28: 0 | N28: 0 | O28: 0 | P28: 0 | Q28: 0 | R28: 0 | S28: 0 | T28: 0 | U28: 0 | V28: 158775
A29: {=XLOOKUP(C29, 'マスタ'!$C$2:$C$312, 'マスタ'!$D$2:$D$312, "マスタ未登録")} -> 旅費交通費 | B29: =IF(AND(C29<>"", COUNTIF('マスタ'!$C:$C, C29)=0), "マスタ未登録", "") | C29: =D29&D134&E29&F29&G29&H29 -> 旅費交通費 | F29: 旅費交通費 | J29: 143057 | K29: 105502 | L29: 0 | M29: 0 | N29: 0 | O29: 0 | P29: 0 | Q29: 0 | R29: 0 | S29: 0 | T29: 0 | U29: 0 | V29: 248559
A30: {=XLOOKUP(C30, 'マスタ'!$C$2:$C$312, 'マスタ'!$D$2:$D$312, "マスタ未登録")} -> 通信費 | B30: =IF(AND(C30<>"", COUNTIF('マスタ'!$C:$C, C30)=0), "マスタ未登録", "") | C30: =D30&D135&E30&F30&G30&H30 -> 通信費 | F30: 通信費 | J30: 157510 | K30: 328433 | L30: 33326 | M30: 0 | N30: 0 | O30: 0 | P30: 0 | Q30: 0 | R30: 0 | S30: 0 | T30: 0 | U30: 0 | V30: 519269
A31: {=XLOOKUP(C31, 'マスタ'!$C$2:$C$312, 'マスタ'!$D$2:$D$312, "マスタ未登録")} -> 消耗品費 | B31: =IF(AND(C31<>"", COUNTIF('マスタ'!$C:$C, C31)=0), "マスタ未登録", "") | C31: =D31&D136&E31&F31&G31&H31 -> 消耗品費 | F31: 消耗品費 | J31: 54825 | K31: 21018 | L31: 1174 | M31: 0 | N31: 0 | O31: 0 | P31: 0 | Q31: 0 | R31: 0 | S31: 0 | T31: 0 | U31: 0 | V31: 77017
A32: {=XLOOKUP(C32, 'マスタ'!$C$2:$C$312, 'マスタ'!$D$2:$D$312, "マスタ未登録")} -> 諸会費 | B32: =IF(AND(C32<>"", COUNTIF('マスタ'!$C:$C, C32)=0), "マスタ未登録", "") | C32: =D32&D137&E32&F32&G32&H32 -> 諸会費 | F32: 諸会費 | J32: 600 | K32: 600 | L32: 0 | M32: 0 | N32: 0 | O32: 0 | P32: 0 | Q32: 0 | R32: 0 | S32: 0 | T32: 0 | U32: 0 | V32: 1200
A33: {=XLOOKUP(C33, 'マスタ'!$C$2:$C$312, 'マスタ'!$D$2:$D$312, "マスタ未登録")} -> 支払手数料 | B33: =IF(AND(C33<>"", COUNTIF('マスタ'!$C:$C, C33)=0), "マスタ未登録", "") | C33: =D33&D138&E33&F33&G33&H33 -> 支払手数料 | F33: 支払手数料 | J33: 25482 | K33: 19700 | L33: 0 | M33: 0 | N33: 0 | O33: 0 | P33: 0 | Q33: 0 | R33: 0 | S33: 0 | T33: 0 | U33: 0 | V33: 45182
A34: {=XLOOKUP(C34, 'マスタ'!$C$2:$C$312, 'マスタ'!$D$2:$D$312, "マスタ未登録")} -> 地代家賃 | B34: =IF(AND(C34<>"", COUNTIF('マスタ'!$C:$C, C34)=0), "マスタ未登録", "") | C34: =D34&D139&E34&F34&G34&H34 -> 地代家賃 | F34: 地代家賃 | J34: 150000 | K34: 170000 | L34: 0 | M34: 0 | N34: 0 | O34: 0 | P34: 0 | Q34: 0 | R34: 0 | S34: 0 | T34: 0 | U34: 0 | V34: 320000
... A38: {=XLOOKUP(C38, 'マスタ'!$C$2:$C$312, 'マスタ'!$D$2:$D$312, "マスタ未登録")} -> 減価償却費 | B38: =IF(AND(C38<>"", COUNTIF('マスタ'!$C:$C, C38)=0), "マスタ未登録", "") | C38: =D38&D143&E38&F38&G38&H38 -> 減価償却費 | F38: 減価償却費 | J38: 12191 | K38: 12191 | L38: 12191 | M38: 12191 | N38: 12191 | O38: 12191 | P38: 12191 | Q38: 12191 | R38: 12191 | S38: 12191 | T38: 12191 | U38: 12197 | V38: 146298
A39: {=XLOOKUP(C39, 'マスタ'!$C$2:$C$312, 'マスタ'!$D$2:$D$312, "マスタ未登録")} -> マスタ未登録 | B39: =IF(AND(C39<>"", COUNTIF('マスタ'!$C:$C, C39)=0), "マスタ未登録", "") -> マスタ未登録 | C39: =D39&D144&E39&F39&G39&H39 -> 販売管理費 計 | E39: 販売管理費 計 | J39: 2532557 | K39: 2836114 | L39: 101691 | M39: 67191 | N39: 67191 | O39: 67191 | P39: 67191 | Q39: 67191 | R39: 67191 | S39: 67191 | T39: 67191 | U39: 67197 | V39: 6075087
A40: {=XLOOKUP(C40, 'マスタ'!$C$2:$C$312, 'マスタ'!$D$2:$D$312, "マスタ未登録")} -> マスタ未登録 | B40: =IF(AND(C40<>"", COUNTIF('マスタ'!$C:$C, C40)=0), "マスタ未登録", "") -> マスタ未登録 | C40: =D40&D145&E40&F40&G40&H40 -> 営業損益金額 | D40: 営業損益金額 | J40: 5545178 | K40: 13481433 | L40: -786379 | M40: -529118 | N40: -529118 | O40: -529118 | P40: -529118 | Q40: -529118 | R40: -529118 | S40: -529118 | T40: -529118 | U40: -529154 | V40: 13478134
A41: {=XLOOKUP(C41, 'マスタ'!$C$2:$C$312, 'マスタ'!$D$2:$D$312, "マスタ未登録")} -> マスタ未登録 | B41: =IF(AND(C41<>"", COUNTIF('マスタ'!$C:$C, C41)=0), "マスタ未登録", "") -> マスタ未登録 | C41: =D41&D146&E41&F41&G41&H41 -> 営業外収益 | E41: 営業外収益 | J41: 1088 | K41: 1248 | L41: 0 | M41: 0 | N41: 0 | O41: 0 | P41: 0 | Q41: 0 | R41: 0 | S41: 0 | T41: 0 | U41: 0 | V41: 2336
A42: {=XLOOKUP(C42, 'マスタ'!$C$2:$C$312, 'マスタ'!$D$2:$D$312, "マスタ未登録")} -> 受取利息 | B42: =IF(AND(C42<>"", COUNTIF('マスタ'!$C:$C, C42)=0), "マスタ未登録", "") | C42: =D42&D147&E42&F42&G42&H42 -> 受取利息 | F42: 受取利息 | J42: 1088 | K42: 1248 | L42: 0 | M42: 0 | N42: 0 | O42: 0 | P42: 0 | Q42: 0 | R42: 0 | S42: 0 | T42: 0 | U42: 0 | V42: 2336
A43: {=XLOOKUP(C43, 'マスタ'!$C$2:$C$312, 'マスタ'!$D$2:$D$312, "マスタ未登録")} -> マスタ未登録 | B43: =IF(AND(C43<>"", COUNTIF('マスタ'!$C:$C, C43)=0), "マスタ未登録", "") -> マスタ未登録 | C43: =D43&D148&E43&F43&G43&H43 -> 営業外費用 | E43: 営業外費用 | J43: 8326 | K43: 0 | L43: 0 | M43: 0 | N43: 0 | O43: 0 | P43: 0 | Q43: 0 | R43: 0 | S43: 0 | T43: 0 | U43: 0 | V43: 8326
...

Sheet UTAITE_PL
D1: 月次推移：損益計算書_株式会社UTAITE（期間：2026年04月〜2027年03月、表示単位：円）
J2: 46113 | K2: 46143 | L2: 46174 | M2: 46204 | N2: 46235 | O2: 46266 | P2: 46296 | Q2: 46327 | R2: 46357 | S2: 46388 | T2: 46419 | U2: 46447 | V2: 期間累計
A3: {=XLOOKUP(C3, 'マスタ'!$C$2:$C$312, 'マスタ'!$D$2:$D$312, "マスタ未登録")} -> マスタ未登録 | D3: 売上高
A4: {=XLOOKUP(C4, 'マスタ'!$C$2:$C$312, 'マスタ'!$D$2:$D$312, "マスタ未登録")} -> マスタ未登録 | B4: =IF(AND(C4<>"", COUNTIF('マスタ'!$C:$C, C4)=0), "マスタ未登録", "") -> マスタ未登録 | C4: =D4&D109&E4&F4&G4&H4 -> 売上高 計 | D4: 売上高 計 | J4: 0 | K4: 0 | L4: 0 | M4: 0 | N4: 0 | O4: 0 | P4: 0 | Q4: 0 | R4: 0 | S4: 0 | T4: 0 | U4: 0 | V4: 0
A5: {=XLOOKUP(C5, 'マスタ'!$C$2:$C$312, 'マスタ'!$D$2:$D$312, "マスタ未登録")} -> マスタ未登録 | B5: =IF(AND(C5<>"", COUNTIF('マスタ'!$C:$C, C5)=0), "マスタ未登録", "") -> マスタ未登録 | C5: =D5&D110&E5&F5&G5&H5 -> 売上原価 | E5: 売上原価
A6: {=XLOOKUP(C6, 'マスタ'!$C$2:$C$312, 'マスタ'!$D$2:$D$312, "マスタ未登録")} -> マスタ未登録 | B6: =IF(AND(C6<>"", COUNTIF('マスタ'!$C:$C, C6)=0), "マスタ未登録", "") -> マスタ未登録 | C6: =D6&D111&E6&F6&G6&H6 -> 売上原価 | E6: 売上原価 | J6: 0 | K6: 0 | L6: 0 | M6: 0 | N6: 0 | O6: 0 | P6: 0 | Q6: 0 | R6: 0 | S6: 0 | T6: 0 | U6: 0 | V6: 0
A7: {=XLOOKUP(C7, 'マスタ'!$C$2:$C$312, 'マスタ'!$D$2:$D$312, "マスタ未登録")} -> 期首商品棚卸高 | B7: =IF(AND(C7<>"", COUNTIF('マスタ'!$C:$C, C7)=0), "マスタ未登録", "") | C7: =D7&D112&E7&F7&G7&H7 -> 期首商品棚卸 | G7: 期首商品棚卸 | J7: 0 | K7: 0 | L7: 0 | M7: 0 | N7: 0 | O7: 0 | P7: 0 | Q7: 0 | R7: 0 | S7: 0 | T7: 0 | U7: 0 | V7: 0
A8: {=XLOOKUP(C8, 'マスタ'!$C$2:$C$312, 'マスタ'!$D$2:$D$312, "マスタ未登録")} -> 当期商品仕入高 | B8: =IF(AND(C8<>"", COUNTIF('マスタ'!$C:$C, C8)=0), "マスタ未登録", "") | C8: =D8&D113&E8&F8&G8&H8 -> 当期商品仕入 | G8: 当期商品仕入 | J8: 0 | K8: 0 | L8: 0 | M8: 0 | N8: 0 | O8: 0 | P8: 0 | Q8: 0 | R8: 0 | S8: 0 | T8: 0 | U8: 0 | V8: 0
A9: {=XLOOKUP(C9, 'マスタ'!$C$2:$C$312, 'マスタ'!$D$2:$D$312, "マスタ未登録")} -> 他勘定振替高 | B9: =IF(AND(C9<>"", COUNTIF('マスタ'!$C:$C, C9)=0), "マスタ未登録", "") | C9: =D9&D114&E9&F9&G9&H9 -> 他勘定振替高(商) | G9: 他勘定振替高(商) | J9: 0 | K9: 0 | L9: 0 | M9: 0 | N9: 0 | O9: 0 | P9: 0 | Q9: 0 | R9: 0 | S9: 0 | T9: 0 | U9: 0 | V9: 0
A10: {=XLOOKUP(C10, 'マスタ'!$C$2:$C$312, 'マスタ'!$D$2:$D$312, "マスタ未登録")} -> 期末商品棚卸高 | B10: =IF(AND(C10<>"", COUNTIF('マスタ'!$C:$C, C10)=0), "マスタ未登録", "") | C10: =D10&D115&E10&F10&G10&H10 -> 期末商品棚卸 | G10: 期末商品棚卸 | J10: 0 | K10: 0 | L10: 0 | M10: 0 | N10: 0 | O10: 0 | P10: 0 | Q10: 0 | R10: 0 | S10: 0 | T10: 0 | U10: 0 | V10: 0
A11: {=XLOOKUP(C11, 'マスタ'!$C$2:$C$312, 'マスタ'!$D$2:$D$312, "マスタ未登録")} -> マスタ未登録 | B11: =IF(AND(C11<>"", COUNTIF('マスタ'!$C:$C, C11)=0), "マスタ未登録", "") -> マスタ未登録 | C11: =D11&D116&E11&F11&G11&H11 -> 商品売上原価 | F11: 商品売上原価 | J11: 0 | K11: 0 | L11: 0 | M11: 0 | N11: 0 | O11: 0 | P11: 0 | Q11: 0 | R11: 0 | S11: 0 | T11: 0 | U11: 0 | V11: 0
A12: {=XLOOKUP(C12, 'マスタ'!$C$2:$C$312, 'マスタ'!$D$2:$D$312, "マスタ未登録")} -> マスタ未登録 | B12: =IF(AND(C12<>"", COUNTIF('マスタ'!$C:$C, C12)=0), "マスタ未登録", "") -> マスタ未登録 | C12: =D12&D117&E12&F12&G12&H12 -> 売上総損益金額 | D12: 売上総損益金額 | J12: 0 | K12: 0 | L12: 0 | M12: 0 | N12: 0 | O12: 0 | P12: 0 | Q12: 0 | R12: 0 | S12: 0 | T12: 0 | U12: 0 | V12: 0
A13: {=XLOOKUP(C13, 'マスタ'!$C$2:$C$312, 'マスタ'!$D$2:$D$312, "マスタ未登録")} -> マスタ未登録 | B13: =IF(AND(C13<>"", COUNTIF('マスタ'!$C:$C, C13)=0), "マスタ未登録", "") -> マスタ未登録 | C13: =D13&D118&E13&F13&G13&H13 -> 販売管理費 | E13: 販売管理費
A14: {=XLOOKUP(C14, 'マスタ'!$C$2:$C$312, 'マスタ'!$D$2:$D$312, "マスタ未登録")} -> 通信費 | B14: =IF(AND(C14<>"", COUNTIF('マスタ'!$C:$C, C14)=0), "マスタ未登録", "") | C14: =D14&D119&E14&F14&G14&H14 -> 通信費 | F14: 通信費 | J14: 0 | K14: 1955 | L14: 0 | M14: 0 | N14: 0 | O14: 0 | P14: 0 | Q14: 0 | R14: 0 | S14: 0 | T14: 0 | U14: 0 | V14: 1955
A15: {=XLOOKUP(C15, 'マスタ'!$C$2:$C$312, 'マスタ'!$D$2:$D$312, "マスタ未登録")} -> 支払報酬 | B15: =IF(AND(C15<>"", COUNTIF('マスタ'!$C:$C, C15)=0), "マスタ未登録", "") | C15: =D15&D120&E15&F15&G15&H15 -> 支払報酬料 | F15: 支払報酬料 | J15: 0 | K15: 55000 | L15: 0 | M15: 0 | N15: 0 | O15: 0 | P15: 0 | Q15: 0 | R15: 0 | S15: 0 | T15: 0 | U15: 0 | V15: 55000
A16: {=XLOOKUP(C16, 'マスタ'!$C$2:$C$312, 'マスタ'!$D$2:$D$312, "マスタ未登録")} -> 支払手数料 | B16: =IF(AND(C16<>"", COUNTIF('マスタ'!$C:$C, C16)=0), "マスタ未登録", "") | C16: =D16&D121&E16&F16&G16&H16 -> 支払手数料 | F16: 支払手数料 | J16: 4200 | K16: 6000 | L16: 1046 | M16: 0 | N16: 0 | O16: 0 | P16: 0 | Q16: 0 | R16: 0 | S16: 0 | T16: 0 | U16: 0 | V16: 11246
A17: {=XLOOKUP(C17, 'マスタ'!$C$2:$C$312, 'マスタ'!$D$2:$D$312, "マスタ未登録")} -> 租税公課 | B17: =IF(AND(C17<>"", COUNTIF('マスタ'!$C:$C, C17)=0), "マスタ未登録", "") | C17: =D17&D122&E17&F17&G17&H17 -> 租税公課 | F17: 租税公課 | J17: 0 | K17: 60820 | L17: 0 | M17: 0 | N17: 0 | O17: 0 | P17: 0 | Q17: 0 | R17: 0 | S17: 0 | T17: 0 | U17: 0 | V17: 60820
A18: {=XLOOKUP(C18, 'マスタ'!$C$2:$C$312, 'マスタ'!$D$2:$D$312, "マスタ未登録")} -> マスタ未登録 | B18: =IF(AND(C18<>"", COUNTIF('マスタ'!$C:$C, C18)=0), "マスタ未登録", "") -> マスタ未登録 | C18: =D18&D123&E18&F18&G18&H18 -> 販売管理費 計 | E18: 販売管理費 計 | J18: 4200 | K18: 123775 | L18: 1046 | M18: 0 | N18: 0 | O18: 0 | P18: 0 | Q18: 0 | R18: 0 | S18: 0 | T18: 0 | U18: 0 | V18: 129021
A19: {=XLOOKUP(C19, 'マスタ'!$C$2:$C$312, 'マスタ'!$D$2:$D$312, "マスタ未登録")} -> マスタ未登録 | B19: =IF(AND(C19<>"", COUNTIF('マスタ'!$C:$C, C19)=0), "マスタ未登録", "") -> マスタ未登録 | C19: =D19&D124&E19&F19&G19&H19 -> 営業損益金額 | D19: 営業損益金額 | J19: -4200 | K19: -123775 | L19: -1046 | M19: 0 | N19: 0 | O19: 0 | P19: 0 | Q19: 0 | R19: 0 | S19: 0 | T19: 0 | U19: 0 | V19: -129021
A20: {=XLOOKUP(C20, 'マスタ'!$C$2:$C$312, 'マスタ'!$D$2:$D$312, "マスタ未登録")} -> マスタ未登録 | B20: =IF(AND(C20<>"", COUNTIF('マスタ'!$C:$C, C20)=0), "マスタ未登録", "") -> マスタ未登録 | C20: =D20&D125&E20&F20&G20&H20 -> 営業外収益 | E20: 営業外収益 | J20: 0 | K20: 0 | L20: 0 | M20: 0 | N20: 0 | O20: 0 | P20: 0 | Q20: 0 | R20: 0 | S20: 0 | T20: 0 | U20: 0 | V20: 0
A21: {=XLOOKUP(C21, 'マスタ'!$C$2:$C$312, 'マスタ'!$D$2:$D$312, "マスタ未登録")} -> マスタ未登録 | B21: =IF(AND(C21<>"", COUNTIF('マスタ'!$C:$C, C21)=0), "マスタ未登録", "") -> マスタ未登録 | C21: =D21&D126&E21&F21&G21&H21 -> 営業外費用 | E21: 営業外費用 | J21: 0 | K21: 0 | L21: 0 | M21: 0 | N21: 0 | O21: 0 | P21: 0 | Q21: 0 | R21: 0 | S21: 0 | T21: 0 | U21: 0 | V21: 0
A22: {=XLOOKUP(C22, 'マスタ'!$C$2:$C$312, 'マスタ'!$D$2:$D$312, "マスタ未登録")} -> マスタ未登録 | B22: =IF(AND(C22<>"", COUNTIF('マスタ'!$C:$C, C22)=0), "マスタ未登録", "") -> マスタ未登録 | C22: =D22&D127&E22&F22&G22&H22 -> 経常損益金額 | D22: 経常損益金額 | J22: -4200 | K22: -123775 | L22: -1046 | M22: 0 | N22: 0 | O22: 0 | P22: 0 | Q22: 0 | R22: 0 | S22: 0 | T22: 0 | U22: 0 | V22: -129021
A23: {=XLOOKUP(C23, 'マスタ'!$C$2:$C$312, 'マスタ'!$D$2:$D$312, "マスタ未登録")} -> マスタ未登録 | B23: =IF(AND(C23<>"", COUNTIF('マスタ'!$C:$C, C23)=0), "マスタ未登録", "") -> マスタ未登録 | C23: =D23&D128&E23&F23&G23&H23 -> 特別利益 | E23: 特別利益 | J23: 0 | K23: 0 | L23: 0 | M23: 0 | N23: 0 | O23: 0 | P23: 0 | Q23: 0 | R23: 0 | S23: 0 | T23: 0 | U23: 0 | V23: 0
A24: {=XLOOKUP(C24, 'マスタ'!$C$2:$C$312, 'マスタ'!$D$2:$D$312, "マスタ未登録")} -> マスタ未登録 | B24: =IF(AND(C24<>"", COUNTIF('マスタ'!$C:$C, C24)=0), "マスタ未登録", "") -> マスタ未登録 | C24: =D24&D129&E24&F24&G24&H24 -> 特別損失 | E24: 特別損失 | J24: 0 | K24: 0 | L24: 0 | M24: 0 | N24: 0 | O24: 0 | P24: 0 | Q24: 0 | R24: 0 | S24: 0 | T24: 0 | U24: 0 | V24: 0
A25: {=XLOOKUP(C25, 'マスタ'!$C$2:$C$312, 'マスタ'!$D$2:$D$312, "マスタ未登録")} -> マスタ未登録 | B25: =IF(AND(C25<>"", COUNTIF('マスタ'!$C:$C, C25)=0), "マスタ未登録", "") -> マスタ未登録 | C25: =D25&D130&E25&F25&G25&H25 -> 税引前当期純損益金額 | D25: 税引前当期純損益金額 | J25: -4200 | K25: -123775 | L25: -1046 | M25: 0 | N25: 0 | O25: 0 | P25: 0 | Q25: 0 | R25: 0 | S25: 0 | T25: 0 | U25: 0 | V25: -129021
A26: {=XLOOKUP(C26, 'マスタ'!$C$2:$C$312, 'マスタ'!$D$2:$D$312, "マスタ未登録")} -> 法人税等 | B26: =IF(AND(C26<>"", COUNTIF('マスタ'!$C:$C, C26)=0), "マスタ未登録", "") | C26: =D26&D131&E26&F26&G26&H26 -> 法人税等 | E26: 法人税等 | J26: 0 | K26: 0 | L26: 0 | M26: 0 | N26: 0 | O26: 0 | P26: 0 | Q26: 0 | R26: 0 | S26: 0 | T26: 0 | U26: 0 | V26: 0
A27: {=XLOOKUP(C27, 'マスタ'!$C$2:$C$312, 'マスタ'!$D$2:$D$312, "マスタ未登録")} -> 法人税等調整額 | B27: =IF(AND(C27<>"", COUNTIF('マスタ'!$C:$C, C27)=0), "マスタ未登録", "") | C27: =D27&D132&E27&F27&G27&H27 -> 法人税等調整額 | E27: 法人税等調整額 | J27: 0 | K27: 0 | L27: 0 | M27: 0 | N27: 0 | O27: 0 | P27: 0 | Q27: 0 | R27: 0 | S27: 0 | T27: 0 | U27: 0 | V27: 0
A28: {=XLOOKUP(C28, 'マスタ'!$C$2:$C$312, 'マスタ'!$D$2:$D$312, "マスタ未登録")} -> マスタ未登録 | B28: =IF(AND(C28<>"", COUNTIF('マスタ'!$C:$C, C28)=0), "マスタ未登録", "") -> マスタ未登録 | C28: =D28&D133&E28&F28&G28&H28 -> 当期純損益金額 | D28: 当期純損益金額 | J28: -4200 | K28: -123775 | L28: -1046 | M28: 0 | N28: 0 | O28: 0 | P28: 0 | Q28: 0 | R28: 0 | S28: 0 | T28: 0 | U28: 0 | V28: -129021

Sheet MD1_PL
D1: MD1
F2: 46113 | G2: 46143 | H2: 46174 | I2: 46204 | J2: 46235 | K2: 46266 | L2: 46296 | M2: 46327 | N2: 46357 | O2: 46388 | P2: 46419 | Q2: 46447 | R2: 決算整理 | S2: 合計
A3: {=XLOOKUP(C3, 'マスタ'!$C$2:$C$312, 'マスタ'!$D$2:$D$312, "マスタ未登録")} -> マスタ未登録 | D3: 売上高
A4: {=XLOOKUP(C4, 'マスタ'!$C$2:$C$312, 'マスタ'!$D$2:$D$312, "マスタ未登録")} -> マスタ未登録 | B4: =IF(AND(C4<>"", COUNTIF('マスタ'!$C:$C, C4)=0), "マスタ未登録", "") -> マスタ未登録 | C4: =D4&D109&E4&F4&G4&H4 -> 売上高00 | E4: 売上高 | F4: 0 | G4: 0 | S4: 0
A5: {=XLOOKUP(C5, 'マスタ'!$C$2:$C$312, 'マスタ'!$D$2:$D$312, "マスタ未登録")} -> マスタ未登録 | B5: =IF(AND(C5<>"", COUNTIF('マスタ'!$C:$C, C5)=0), "マスタ未登録", "") -> マスタ未登録 | C5: =D5&D110&E5&F5&G5&H5 -> 売上高合計00 | D5: 売上高合計 | F5: 0 | G5: 0 | S5: 0
A6: {=XLOOKUP(C6, 'マスタ'!$C$2:$C$312, 'マスタ'!$D$2:$D$312, "マスタ未登録")} -> マスタ未登録 | B6: =IF(AND(C6<>"", COUNTIF('マスタ'!$C:$C, C6)=0), "マスタ未登録", "") -> マスタ未登録 | C6: =D6&D111&E6&F6&G6&H6 -> 売上原価 | D6: 売上原価
A7: {=XLOOKUP(C7, 'マスタ'!$C$2:$C$312, 'マスタ'!$D$2:$D$312, "マスタ未登録")} -> マスタ未登録 | B7: =IF(AND(C7<>"", COUNTIF('マスタ'!$C:$C, C7)=0), "マスタ未登録", "") -> マスタ未登録 | C7: =D7&D112&E7&F7&G7&H7 -> 売上原価合計00 | D7: 売上原価合計 | F7: 0 | G7: 0 | S7: 0
A8: {=XLOOKUP(C8, 'マスタ'!$C$2:$C$312, 'マスタ'!$D$2:$D$312, "マスタ未登録")} -> マスタ未登録 | B8: =IF(AND(C8<>"", COUNTIF('マスタ'!$C:$C, C8)=0), "マスタ未登録", "") -> マスタ未登録 | C8: =D8&D113&E8&F8&G8&H8 -> 売上総利益00 | D8: 売上総利益 | F8: 0 | G8: 0 | S8: 0
A9: {=XLOOKUP(C9, 'マスタ'!$C$2:$C$312, 'マスタ'!$D$2:$D$312, "マスタ未登録")} -> マスタ未登録 | B9: =IF(AND(C9<>"", COUNTIF('マスタ'!$C:$C, C9)=0), "マスタ未登録", "") -> マスタ未登録 | C9: =D9&D114&E9&F9&G9&H9 -> 販売費及び一般管理費 | D9: 販売費及び一般管理費
A10: {=XLOOKUP(C10, 'マスタ'!$C$2:$C$312, 'マスタ'!$D$2:$D$312, "マスタ未登録")} -> マスタ未登録 | B10: =IF(AND(C10<>"", COUNTIF('マスタ'!$C:$C, C10)=0), "マスタ未登録", "") -> マスタ未登録 | C10: =D10&D115&E10&F10&G10&H10 -> 消耗品費00 | E10: 消耗品費 | F10: 0 | G10: 0 | S10: 0
A11: {=XLOOKUP(C11, 'マスタ'!$C$2:$C$312, 'マスタ'!$D$2:$D$312, "マスタ未登録")} -> マスタ未登録 | B11: =IF(AND(C11<>"", COUNTIF('マスタ'!$C:$C, C11)=0), "マスタ未登録", "") -> マスタ未登録 | C11: =D11&D116&E11&F11&G11&H11 -> 租税公課00 | E11: 租税公課 | F11: 0 | G11: 0 | S11: 0
A12: {=XLOOKUP(C12, 'マスタ'!$C$2:$C$312, 'マスタ'!$D$2:$D$312, "マスタ未登録")} -> マスタ未登録 | B12: =IF(AND(C12<>"", COUNTIF('マスタ'!$C:$C, C12)=0), "マスタ未登録", "") -> マスタ未登録 | C12: =D12&D117&E12&F12&G12&H12 -> 支払手数料00 | E12: 支払手数料 | F12: 0 | G12: 0 | S12: 0
A13: {=XLOOKUP(C13, 'マスタ'!$C$2:$C$312, 'マスタ'!$D$2:$D$312, "マスタ未登録")} -> マスタ未登録 | B13: =IF(AND(C13<>"", COUNTIF('マスタ'!$C:$C, C13)=0), "マスタ未登録", "") -> マスタ未登録 | C13: =D13&D118&E13&F13&G13&H13 -> 支払報酬00 | E13: 支払報酬 | F13: 0 | G13: 0 | S13: 0
A14: {=XLOOKUP(C14, 'マスタ'!$C$2:$C$312, 'マスタ'!$D$2:$D$312, "マスタ未登録")} -> マスタ未登録 | B14: =IF(AND(C14<>"", COUNTIF('マスタ'!$C:$C, C14)=0), "マスタ未登録", "") -> マスタ未登録 | C14: =D14&D119&E14&F14&G14&H14 -> 販売費及び一般管理費合計00 | D14: 販売費及び一般管理費合計 | F14: 0 | G14: 0 | S14: 0
A15: {=XLOOKUP(C15, 'マスタ'!$C$2:$C$312, 'マスタ'!$D$2:$D$312, "マスタ未登録")} -> マスタ未登録 | B15: =IF(AND(C15<>"", COUNTIF('マスタ'!$C:$C, C15)=0), "マスタ未登録", "") -> マスタ未登録 | C15: =D15&D120&E15&F15&G15&H15 -> 営業利益00 | D15: 営業利益 | F15: 0 | G15: 0 | S15: 0
A16: {=XLOOKUP(C16, 'マスタ'!$C$2:$C$312, 'マスタ'!$D$2:$D$312, "マスタ未登録")} -> マスタ未登録 | B16: =IF(AND(C16<>"", COUNTIF('マスタ'!$C:$C, C16)=0), "マスタ未登録", "") -> マスタ未登録 | C16: =D16&D121&E16&F16&G16&H16 -> 受取利息00 | E16: 受取利息 | F16: 0 | G16: 0 | S16: 0
A17: {=XLOOKUP(C17, 'マスタ'!$C$2:$C$312, 'マスタ'!$D$2:$D$312, "マスタ未登録")} -> マスタ未登録 | B17: =IF(AND(C17<>"", COUNTIF('マスタ'!$C:$C, C17)=0), "マスタ未登録", "") -> マスタ未登録 | C17: =D17&D122&E17&F17&G17&H17 -> 営業外収益00 | D17: 営業外収益 | F17: 0 | G17: 0 | S17: 0
A18: {=XLOOKUP(C18, 'マスタ'!$C$2:$C$312, 'マスタ'!$D$2:$D$312, "マスタ未登録")} -> マスタ未登録 | B18: =IF(AND(C18<>"", COUNTIF('マスタ'!$C:$C, C18)=0), "マスタ未登録", "") -> マスタ未登録 | C18: =D18&D123&E18&F18&G18&H18 -> 営業外収益合計00 | D18: 営業外収益合計 | F18: 0 | G18: 0 | S18: 0
A19: {=XLOOKUP(C19, 'マスタ'!$C$2:$C$312, 'マスタ'!$D$2:$D$312, "マスタ未登録")} -> マスタ未登録 | B19: =IF(AND(C19<>"", COUNTIF('マスタ'!$C:$C, C19)=0), "マスタ未登録", "") -> マスタ未登録 | C19: =D19&D124&E19&F19&G19&H19 -> 営業外費用00 | D19: 営業外費用 | F19: 0 | G19: 0 | S19: 0
A20: {=XLOOKUP(C20, 'マスタ'!$C$2:$C$312, 'マスタ'!$D$2:$D$312, "マスタ未登録")} -> マスタ未登録 | B20: =IF(AND(C20<>"", COUNTIF('マスタ'!$C:$C, C20)=0), "マスタ未登録", "") -> マスタ未登録 | C20: =D20&D125&E20&F20&G20&H20 -> 営業外費用合計00 | D20: 営業外費用合計 | F20: 0 | G20: 0 | S20: 0
A21: {=XLOOKUP(C21, 'マスタ'!$C$2:$C$312, 'マスタ'!$D$2:$D$312, "マスタ未登録")} -> マスタ未登録 | B21: =IF(AND(C21<>"", COUNTIF('マスタ'!$C:$C, C21)=0), "マスタ未登録", "") -> マスタ未登録 | C21: =D21&D126&E21&F21&G21&H21 -> 経常利益00 | D21: 経常利益 | F21: 0 | G21: 0 | S21: 0
A22: {=XLOOKUP(C22, 'マスタ'!$C$2:$C$312, 'マスタ'!$D$2:$D$312, "マスタ未登録")} -> マスタ未登録 | B22: =IF(AND(C22<>"", COUNTIF('マスタ'!$C:$C, C22)=0), "マスタ未登録", "") -> マスタ未登録 | C22: =D22&D127&E22&F22&G22&H22 -> 特別利益00 | D22: 特別利益 | F22: 0 | G22: 0 | S22: 0
A23: {=XLOOKUP(C23, 'マスタ'!$C$2:$C$312, 'マスタ'!$D$2:$D$312, "マスタ未登録")} -> マスタ未登録 | B23: =IF(AND(C23<>"", COUNTIF('マスタ'!$C:$C, C23)=0), "マスタ未登録", "") -> マスタ未登録 | C23: =D23&D128&E23&F23&G23&H23 -> 特別利益合計00 | D23: 特別利益合計 | F23: 0 | G23: 0 | S23: 0
A24: {=XLOOKUP(C24, 'マスタ'!$C$2:$C$312, 'マスタ'!$D$2:$D$312, "マスタ未登録")} -> マスタ未登録 | B24: =IF(AND(C24<>"", COUNTIF('マスタ'!$C:$C, C24)=0), "マスタ未登録", "") -> マスタ未登録 | C24: =D24&D129&E24&F24&G24&H24 -> 特別損失00 | D24: 特別損失 | F24: 0 | G24: 0 | S24: 0
A25: {=XLOOKUP(C25, 'マスタ'!$C$2:$C$312, 'マスタ'!$D$2:$D$312, "マスタ未登録")} -> マスタ未登録 | B25: =IF(AND(C25<>"", COUNTIF('マスタ'!$C:$C, C25)=0), "マスタ未登録", "") -> マスタ未登録 | C25: =D25&D130&E25&F25&G25&H25 -> 特別損失合計00 | D25: 特別損失合計 | F25: 0 | G25: 0 | S25: 0
A26: {=XLOOKUP(C26, 'マスタ'!$C$2:$C$312, 'マスタ'!$D$2:$D$312, "マスタ未登録")} -> マスタ未登録 | B26: =IF(AND(C26<>"", COUNTIF('マスタ'!$C:$C, C26)=0), "マスタ未登録", "") -> マスタ未登録 | C26: =D26&D131&E26&F26&G26&H26 -> 税引前当期純利益00 | D26: 税引前当期純利益 | F26: 0 | G26: 0 | S26: 0
A27: {=XLOOKUP(C27, 'マスタ'!$C$2:$C$312, 'マスタ'!$D$2:$D$312, "マスタ未登録")} -> マスタ未登録 | B27: =IF(AND(C27<>"", COUNTIF('マスタ'!$C:$C, C27)=0), "マスタ未登録", "") -> マスタ未登録 | C27: =D27&D132&E27&F27&G27&H27 -> 法人税00 | D27: 法人税 | F27: 0 | G27: 0 | S27: 0
A28: {=XLOOKUP(C28, 'マスタ'!$C$2:$C$312, 'マスタ'!$D$2:$D$312, "マスタ未登録")} -> マスタ未登録 | B28: =IF(AND(C28<>"", COUNTIF('マスタ'!$C:$C, C28)=0), "マスタ未登録", "") -> マスタ未登録 | C28: =D28&D133&E28&F28&G28&H28 -> 当期純利益00 | D28: 当期純利益 | F28: 0 | G28: 0 | S28: 0

Sheet VO_PL
B1: ②マスタ結びつけ | C1: ① | D1: 月次推移：損益計算書_株式会社VOISING（期間：2026年04月〜2027年03月、表示単位：円）
J2: 46113 | K2: 46143 | L2: 46174 | M2: 46204 | N2: 46235 | O2: 46266 | P2: 46296 | Q2: 46327 | R2: 46357 | S2: 46388 | T2: 46419 | U2: 46447 | V2: 期間累計
D3: 売上高
